Workbook

Sheet Start_page

Sheet Data1
A1: =$O$1/100 -> 0.02 | B1: {=1-COS((_xlfn.SEQUENCE(500,1,0,1)*PI())/(2*(500-1)))} -> 0 | C1: =IF($A$1=0, 0, IF(B1<=$A$2, ($A$1/$A$2^2)*(2*$A$2*B1-B1^2), ($A$1/(1-$A$2)^2)*((1-2*$A$2)+2*$A$2*B1-B1^2))) -> 0 | D1: =IF($Q$3, 5*$A$3*(0.2969*SQRT(B1)-0.126*B1-0.3516*B1^2+0.2843*B1^3-0.1036*B1^4), 5*$A$3*(0.2969*SQRT(B1)-0.126*B1-0.3516*B1^2+0.2843*B1^3-0.1015*B1^4)) -> 0 | E1: =IF($A$1=0, 0, IF(B1<=$A$2, ($A$1/$A$2^2) *(2*$A$2-2*B1), ($A$1/(1-$A$2)^2)*(2*$A$2-2*B1))) -> 0.1 | F1: =IF($A$1=0, 0, ATAN(E1)) -> 0.099668652 | G1: =B1-D1*SIN(F1) -> 0 | H1: =C1+D1*COS(F1) -> 0 | I1: =B1+D1*SIN(F1) -> 0 | J1: =C1-D1*COS(F1) -> 0 | M1: =IF($Q$1, C1, -0.5) -> -0.5 | N1: 2 | O1: =IF($P$1=1, 0, $N$1) -> 2 | P1: 2 | Q1: FALSE | R1: =ATAN(E1) -> 0.099668652 | S1: {=_xlfn.SEQUENCE(50, 1, 0, (2*PI())/(50-1))} -> 0 | T1: =$R$2*(COS($R$1)+COS(S1)) -> 0.031655115 | U1: =IF($Q$2, $R$2*(SIN($R$1)+SIN(S1)), -0.5) -> -0.5
A2: =$O$2/10 -> 0.4 | B2: 4.9545967e-06 | C2: =IF($A$1=0, 0, IF(B2<=$A$2, ($A$1/$A$2^2)*(2*$A$2*B2-B2^2), ($A$1/(1-$A$2)^2)*((1-2*$A$2)+2*$A$2*B2-B2^2))) -> 4.954566e-07 | D2: =IF($Q$3, 5*$A$3*(0.2969*SQRT(B2)-0.126*B2-0.3516*B2^2+0.2843*B2^3-0.1036*B2^4), 5*$A$3*(0.2969*SQRT(B2)-0.126*B2-0.3516*B2^2+0.2843*B2^3-0.1015*B2^4)) -> 0.00039614589 | E2: =IF($A$1=0, 0, IF(B2<=$A$2, ($A$1/$A$2^2) *(2*$A$2-2*B2), ($A$1/(1-$A$2)^2)*(2*$A$2-2*B2))) -> 0.099998761 | F2: =IF($A$1=0, 0, ATAN(E2)) -> 0.099667426 | G2: =B2-D2*SIN(F2) -> -3.4462909e-05 | H2: =C2+D2*COS(F2) -> 0.0003946754 | I2: =B2+D2*SIN(F2) -> 4.4372102e-05 | J2: =C2-D2*COS(F2) -> -0.00039368448 | M2: =IF($Q$1, C2, -0.5) -> -0.5 | N2: 4 | O2: =IF($P$1=1, 0, $N$2) -> 4 | Q2: FALSE | R2: =(0.2969^2/2)*(A3/0.2)^2 -> 0.01586693 | S2: 0.12822827 | T2: =$R$2*(COS($R$1)+COS(S2)) -> 0.031524848 | U2: =IF($Q$2, $R$2*(SIN($R$1)+SIN(S2)), -0.5) -> -0.5
A3: =O3/100 -> 0.12 | B3: 1.9818338e-05 | C3: =IF($A$1=0, 0, IF(B3<=$A$2, ($A$1/$A$2^2)*(2*$A$2*B3-B3^2), ($A$1/(1-$A$2)^2)*((1-2*$A$2)+2*$A$2*B3-B3^2))) -> 1.9817847e-06 | D3: =IF($Q$3, 5*$A$3*(0.2969*SQRT(B3)-0.126*B3-0.3516*B3^2+0.2843*B3^3-0.1036*B3^4), 5*$A$3*(0.2969*SQRT(B3)-0.126*B3-0.3516*B3^2+0.2843*B3^3-0.1015*B3^4)) -> 0.00079154159 | E3: =IF($A$1=0, 0, IF(B3<=$A$2, ($A$1/$A$2^2) *(2*$A$2-2*B3), ($A$1/(1-$A$2)^2)*(2*$A$2-2*B3))) -> 0.099995045 | F3: =IF($A$1=0, 0, ATAN(E3)) -> 0.099663747 | G3: =B3-D3*SIN(F3) -> -5.8939131e-05 | H3: =C3+D3*COS(F3) -> 0.00078959549 | I3: =B3+D3*SIN(F3) -> 9.8575806e-05 | J3: =C3-D3*COS(F3) -> -0.00078563192 | M3: =IF($Q$1, C3, -0.5) -> -0.5 | O3: 12 | Q3: FALSE | S3: 0.25645654 | T3: =$R$2*(COS($R$1)+COS(S3)) -> 0.031136185 | U3: =IF($Q$2, $R$2*(SIN($R$1)+SIN(S3)), -0.5) -> -0.5
B4: 4.4591076e-05 | C4: =IF($A$1=0, 0, IF(B4<=$A$2, ($A$1/$A$2^2)*(2*$A$2*B4-B4^2), ($A$1/(1-$A$2)^2)*((1-2*$A$2)+2*$A$2*B4-B4^2))) -> 4.458859e-06 | D4: =IF($Q$3, 5*$A$3*(0.2969*SQRT(B4)-0.126*B4-0.3516*B4^2+0.2843*B4^3-0.1036*B4^4), 5*$A$3*(0.2969*SQRT(B4)-0.126*B4-0.3516*B4^2+0.2843*B4^3-0.1015*B4^4)) -> 0.0011861859 | E4: =IF($A$1=0, 0, IF(B4<=$A$2, ($A$1/$A$2^2) *(2*$A$2-2*B4), ($A$1/(1-$A$2)^2)*(2*$A$2-2*B4))) -> 0.099988852 | F4: =IF($A$1=0, 0, ATAN(E4)) -> 0.099657615 | G4: =B4-D4*SIN(F4) -> -7.342581e-05 | H4: =C4+D4*COS(F4) -> 0.0011847593 | I4: =B4+D4*SIN(F4) -> 0.00016260796 | J4: =C4-D4*COS(F4) -> -0.0011758416 | M4: =IF($Q$1, C4, -0.5) -> -0.5 | S4: 0.38468481 | T4: =$R$2*(COS($R$1)+COS(S4)) -> 0.030495508 | U4: =IF($Q$2, $R$2*(SIN($R$1)+SIN(S4)), -0.5) -> -0.5
B5: 7.9272565e-05 | C5: =IF($A$1=0, 0, IF(B5<=$A$2, ($A$1/$A$2^2)*(2*$A$2*B5-B5^2), ($A$1/(1-$A$2)^2)*((1-2*$A$2)+2*$A$2*B5-B5^2))) -> 7.926471e-06 | D5: =IF($Q$3, 5*$A$3*(0.2969*SQRT(B5)-0.126*B5-0.3516*B5^2+0.2843*B5^3-0.1036*B5^4), 5*$A$3*(0.2969*SQRT(B5)-0.126*B5-0.3516*B5^2+0.2843*B5^3-0.1015*B5^4)) -> 0.0015800777 | E5: =IF($A$1=0, 0, IF(B5<=$A$2, ($A$1/$A$2^2) *(2*$A$2-2*B5), ($A$1/(1-$A$2)^2)*(2*$A$2-2*B5))) -> 0.099980182 | F5: =IF($A$1=0, 0, ATAN(E5)) -> 0.099649031 | G5: =B5-D5*SIN(F5) -> -7.7920191e-05 | H5: =C5+D5*COS(F5) -> 0.0015801656 | I5: =B5+D5*SIN(F5) -> 0.00023646532 | J5: =C5-D5*COS(F5) -> -0.0015643127 | M5: =IF($Q$1, C5, -0.5) -> -0.5 | S5: 0.51291309 | T5: =$R$2*(COS($R$1)+COS(S5)) -> 0.029613338 | U5: =IF($Q$2, $R$2*(SIN($R$1)+SIN(S5)), -0.5) -> -0.5
B6: 0.00012386246 | C6: =IF($A$1=0, 0, IF(B6<=$A$2, ($A$1/$A$2^2)*(2*$A$2*B6-B6^2), ($A$1/(1-$A$2)^2)*((1-2*$A$2)+2*$A$2*B6-B6^2))) -> 1.2384329e-05 | D6: =IF($Q$3, 5*$A$3*(0.2969*SQRT(B6)-0.126*B6-0.3516*B6^2+0.2843*B6^3-0.1036*B6^4), 5*$A$3*(0.2969*SQRT(B6)-0.126*B6-0.3516*B6^2+0.2843*B6^3-0.1015*B6^4)) -> 0.0019732154 | E6: =IF($A$1=0, 0, IF(B6<=$A$2, ($A$1/$A$2^2) *(2*$A$2-2*B6), ($A$1/(1-$A$2)^2)*(2*$A$2-2*B6))) -> 0.099969034 | F6: =IF($A$1=0, 0, ATAN(E6)) -> 0.099637993 | G6: =B6-D6*SIN(F6) -> -7.2419613e-05 | H6: =C6+D6*COS(F6) -> 0.0019758131 | I6: =B6+D6*SIN(F6) -> 0.00032014454 | J6: =C6-D6*COS(F6) -> -0.0019510444 | M6: =IF($Q$1, C6, -0.5) -> -0.5 | S6: 0.64114136 | T6: =$R$2*(COS($R$1)+COS(S6)) -> 0.028504159 | U6: =IF($Q$2, $R$2*(SIN($R$1)+SIN(S6)), -0.5) -> -0.5
B7: 0.00017836033 | C7: =IF($A$1=0, 0, IF(B7<=$A$2, ($A$1/$A$2^2)*(2*$A$2*B7-B7^2), ($A$1/(1-$A$2)^2)*((1-2*$A$2)+2*$A$2*B7-B7^2))) -> 1.7832056e-05 | D7: =IF($Q$3, 5*$A$3*(0.2969*SQRT(B7)-0.126*B7-0.3516*B7^2+0.2843*B7^3-0.1036*B7^4), 5*$A$3*(0.2969*SQRT(B7)-0.126*B7-0.3516*B7^2+0.2843*B7^3-0.1015*B7^4)) -> 0.0023655976 | E7: =IF($A$1=0, 0, IF(B7<=$A$2, ($A$1/$A$2^2) *(2*$A$2-2*B7), ($A$1/(1-$A$2)^2)*(2*$A$2-2*B7))) -> 0.09995541 | F7: =IF($A$1=0, 0, ATAN(E7)) -> 0.099624504 | G7: =B7-D7*SIN(F7) -> -5.6921516e-05 | H7: =C7+D7*COS(F7) -> 0.0023717001 | I7: =B7+D7*SIN(F7) -> 0.00041364217 | J7: =C7-D7*COS(F7) -> -0.002336036 | M7: =IF($Q$1, C7, -0.5) -> -0.5 | S7: 0.76936963 | T7: =$R$2*(COS($R$1)+COS(S7)) -> 0.027186184 | U7: =IF($Q$2, $R$2*(SIN($R$1)+SIN(S7)), -0.5) -> -0.5
B8: 0.00024276562 | C8: =IF($A$1=0, 0, IF(B8<=$A$2, ($A$1/$A$2^2)*(2*$A$2*B8-B8^2), ($A$1/(1-$A$2)^2)*((1-2*$A$2)+2*$A$2*B8-B8^2))) -> 2.4269195e-05 | D8: =IF($Q$3, 5*$A$3*(0.2969*SQRT(B8)-0.126*B8-0.3516*B8^2+0.2843*B8^3-0.1036*B8^4), 5*$A$3*(0.2969*SQRT(B8)-0.126*B8-0.3516*B8^2+0.2843*B8^3-0.1015*B8^4)) -> 0.0027572227 | E8: =IF($A$1=0, 0, IF(B8<=$A$2, ($A$1/$A$2^2) *(2*$A$2-2*B8), ($A$1/(1-$A$2)^2)*(2*$A$2-2*B8))) -> 0.099939309 | F8: =IF($A$1=0, 0, ATAN(E8)) -> 0.099608562 | G8: =B8-D8*SIN(F8) -> -3.1423436e-05 | H8: =C8+D8*COS(F8) -> 0.0027678248 | I8: =B8+D8*SIN(F8) -> 0.00051695467 | J8: =C8-D8*COS(F8) -> -0.0027192864 | M8: =IF($Q$1, C8, -0.5) -> -0.5 | S8: 0.8975979 | T8: =$R$2*(COS($R$1)+COS(S8)) -> 0.025681054 | U8: =IF($Q$2, $R$2*(SIN($R$1)+SIN(S8)), -0.5) -> -0.5
B9: 0.00031707769 | C9: =IF($A$1=0, 0, IF(B9<=$A$2, ($A$1/$A$2^2)*(2*$A$2*B9-B9^2), ($A$1/(1-$A$2)^2)*((1-2*$A$2)+2*$A$2*B9-B9^2))) -> 3.1695202e-05 | D9: =IF($Q$3, 5*$A$3*(0.2969*SQRT(B9)-0.126*B9-0.3516*B9^2+0.2843*B9^3-0.1036*B9^4), 5*$A$3*(0.2969*SQRT(B9)-0.126*B9-0.3516*B9^2+0.2843*B9^3-0.1015*B9^4)) -> 0.0031480889 | E9: =IF($A$1=0, 0, IF(B9<=$A$2, ($A$1/$A$2^2) *(2*$A$2-2*B9), ($A$1/(1-$A$2)^2)*(2*$A$2-2*B9))) -> 0.099920731 | F9: =IF($A$1=0, 0, ATAN(E9)) -> 0.099590167 | G9: =B9-D9*SIN(F9) -> 4.0769926e-06 | H9: =C9+D9*COS(F9) -> 0.0031641853 | I9: =B9+D9*SIN(F9) -> 0.00063007839 | J9: =C9-D9*COS(F9) -> -0.0031007949 | M9: =IF($Q$1, C9, -0.5) -> -0.5 | S9: 1.0258262 | T9: =$R$2*(COS($R$1)+COS(S9)) -> 0.024013484 | U9: =IF($Q$2, $R$2*(SIN($R$1)+SIN(S9)), -0.5) -> -0.5
B10: 0.00040129582 | C10: =IF($A$1=0, 0, IF(B10<=$A$2, ($A$1/$A$2^2)*(2*$A$2*B10-B10^2), ($A$1/(1-$A$2)^2)*((1-2*$A$2)+2*$A$2*B10-B10^2))) -> 4.0109452e-05 | D10: =IF($Q$3, 5*$A$3*(0.2969*SQRT(B10)-0.126*B10-0.3516*B10^2+0.2843*B10^3-0.1036*B10^4), 5*$A$3*(0.2969*SQRT(B10)-0.126*B10-0.3516*B10^2+0.2843*B10^3-0.1015*B10^4)) -> 0.0035381943 | E10: =IF($A$1=0, 0, IF(B10<=$A$2, ($A$1/$A$2^2) *(2*$A$2-2*B10), ($A$1/(1-$A$2)^2)*(2*$A$2-2*B10))) -> 0.099899676 | F10: =IF($A$1=0, 0, ATAN(E10)) -> 0.099569321 | G10: =B10-D10*SIN(F10) -> 4.9582037e-05 | H10: =C10+D10*COS(F10) -> 0.0035607794 | I10: =B10+D10*SIN(F10) -> 0.0007530096 | J10: =C10-D10*COS(F10) -> -0.0034805605 | M10: =IF($Q$1, C10, -0.5) -> -0.5 | S10: 1.1540544 | T10: =$R$2*(COS($R$1)+COS(S10)) -> 0.022210854 | U10: =IF($Q$2, $R$2*(SIN($R$1)+SIN(S10)), -0.5) -> -0.5
B11: 0.00049541917 | C11: =IF($A$1=0, 0, IF(B11<=$A$2, ($A$1/$A$2^2)*(2*$A$2*B11-B11^2), ($A$1/(1-$A$2)^2)*((1-2*$A$2)+2*$A$2*B11-B11^2))) -> 4.9511237e-05 | D11: =IF($Q$3, 5*$A$3*(0.2969*SQRT(B11)-0.126*B11-0.3516*B11^2+0.2843*B11^3-0.1036*B11^4), 5*$A$3*(0.2969*SQRT(B11)-0.126*B11-0.3516*B11^2+0.2843*B11^3-0.1015*B11^4)) -> 0.0039275371 | E11: =IF($A$1=0, 0, IF(B11<=$A$2, ($A$1/$A$2^2) *(2*$A$2-2*B11), ($A$1/(1-$A$2)^2)*(2*$A$2-2*B11))) -> 0.099876145 | F11: =IF($A$1=0, 0, ATAN(E11)) -> 0.099546022 | G11: =B11-D11*SIN(F11) -> 0.00010509387 | H11: =C11+D11*COS(F11) -> 0.0039576046 | I11: =B11+D11*SIN(F11) -> 0.00088574447 | J11: =C11-D11*COS(F11) -> -0.0038585821 | M11: =IF($Q$1, C11, -0.5) -> -0.5 | S11: 1.2822827 | T11: =$R$2*(COS($R$1)+COS(S11)) -> 0.020302764 | U11: =IF($Q$2, $R$2*(SIN($R$1)+SIN(S11)), -0.5) -> -0.5
B12: 0.0005994468 | C12: =IF($A$1=0, 0, IF(B12<=$A$2, ($A$1/$A$2^2)*(2*$A$2*B12-B12^2), ($A$1/(1-$A$2)^2)*((1-2*$A$2)+2*$A$2*B12-B12^2))) -> 5.9899763e-05 | D12: =IF($Q$3, 5*$A$3*(0.2969*SQRT(B12)-0.126*B12-0.3516*B12^2+0.2843*B12^3-0.1036*B12^4), 5*$A$3*(0.2969*SQRT(B12)-0.126*B12-0.3516*B12^2+0.2843*B12^3-0.1015*B12^4)) -> 0.004316115 | E12: =IF($A$1=0, 0, IF(B12<=$A$2, ($A$1/$A$2^2) *(2*$A$2-2*B12), ($A$1/(1-$A$2)^2)*(2*$A$2-2*B12))) -> 0.099850138 | F12: =IF($A$1=0, 0, ATAN(E12)) -> 0.099520272 | G12: =B12-D12*SIN(F12) -> 0.00017061455 | H12: =C12+D12*COS(F12) -> 0.0043546584 | I12: =B12+D12*SIN(F12) -> 0.001028279 | J12: =C12-D12*COS(F12) -> -0.0042348589 | M12: =IF($Q$1, C12, -0.5) -> -0.5 | S12: 1.410511 | T12: =$R$2*(COS($R$1)+COS(S12)) -> 0.018320546 | U12: =IF($Q$2, $R$2*(SIN($R$1)+SIN(S12)), -0.5) -> -0.5
B13: 0.00071337768 | C13: =IF($A$1=0, 0, IF(B13<=$A$2, ($A$1/$A$2^2)*(2*$A$2*B13-B13^2), ($A$1/(1-$A$2)^2)*((1-2*$A$2)+2*$A$2*B13-B13^2))) -> 7.1274154e-05 | D13: =IF($Q$3, 5*$A$3*(0.2969*SQRT(B13)-0.126*B13-0.3516*B13^2+0.2843*B13^3-0.1036*B13^4), 5*$A$3*(0.2969*SQRT(B13)-0.126*B13-0.3516*B13^2+0.2843*B13^3-0.1015*B13^4)) -> 0.0047039259 | E13: =IF($A$1=0, 0, IF(B13<=$A$2, ($A$1/$A$2^2) *(2*$A$2-2*B13), ($A$1/(1-$A$2)^2)*(2*$A$2-2*B13))) -> 0.099821656 | F13: =IF($A$1=0, 0, ATAN(E13)) -> 0.099492071 | G13: =B13-D13*SIN(F13) -> 0.00024614607 | H13: =C13+D13*COS(F13) -> 0.004751938 | I13: =B13+D13*SIN(F13) -> 0.0011806093 | J13: =C13-D13*COS(F13) -> -0.0046093897 | M13: =IF($Q$1, C13, -0.5) -> -0.5 | S13: 1.5387393 | T13: =$R$2*(COS($R$1)+COS(S13)) -> 0.016296745 | U13: =IF($Q$2, $R$2*(SIN($R$1)+SIN(S13)), -0.5) -> -0.5
B14: 0.00083721069 | C14: =IF($A$1=0, 0, IF(B14<=$A$2, ($A$1/$A$2^2)*(2*$A$2*B14-B14^2), ($A$1/(1-$A$2)^2)*((1-2*$A$2)+2*$A$2*B14-B14^2))) -> 8.3633453e-05 | D14: =IF($Q$3, 5*$A$3*(0.2969*SQRT(B14)-0.126*B14-0.3516*B14^2+0.2843*B14^3-0.1036*B14^4), 5*$A$3*(0.2969*SQRT(B14)-0.126*B14-0.3516*B14^2+0.2843*B14^3-0.1015*B14^4)) -> 0.0050909675 | E14: =IF($A$1=0, 0, IF(B14<=$A$2, ($A$1/$A$2^2) *(2*$A$2-2*B14), ($A$1/(1-$A$2)^2)*(2*$A$2-2*B14))) -> 0.099790697 | F14: =IF($A$1=0, 0, ATAN(E14)) -> 0.099461418 | G14: =B14-D14*SIN(F14) -> 0.00033169028 | H14: =C14+D14*COS(F14) -> 0.0051494404 | I14: =B14+D14*SIN(F14) -> 0.0013427311 | J14: =C14-D14*COS(F14) -> -0.0049821735 | M14: =IF($Q$1, C14, -0.5) -> -0.5 | S14: 1.6669675 | T14: =$R$2*(COS($R$1)+COS(S14)) -> 0.014264595 | U14: =IF($Q$2, $R$2*(SIN($R$1)+SIN(S14)), -0.5) -> -0.5
B15: 0.00097094459 | C15: =IF($A$1=0, 0, IF(B15<=$A$2, ($A$1/$A$2^2)*(2*$A$2*B15-B15^2), ($A$1/(1-$A$2)^2)*((1-2*$A$2)+2*$A$2*B15-B15^2))) -> 9.6976617e-05 | D15: =IF($Q$3, 5*$A$3*(0.2969*SQRT(B15)-0.126*B15-0.3516*B15^2+0.2843*B15^3-0.1036*B15^4), 5*$A$3*(0.2969*SQRT(B15)-0.126*B15-0.3516*B15^2+0.2843*B15^3-0.1015*B15^4)) -> 0.0054772374 | E15: =IF($A$1=0, 0, IF(B15<=$A$2, ($A$1/$A$2^2) *(2*$A$2-2*B15), ($A$1/(1-$A$2)^2)*(2*$A$2-2*B15))) -> 0.099757264 | F15: =IF($A$1=0, 0, ATAN(E15)) -> 0.099428314 | G15: =B15-D15*SIN(F15) -> 0.00042724898 | H15: =C15+D15*COS(F15) -> 0.0055471623 | I15: =B15+D15*SIN(F15) -> 0.0015146402 | J15: =C15-D15*COS(F15) -> -0.0053532091 | M15: =IF($Q$1, C15, -0.5) -> -0.5 | S15: 1.7951958 | T15: =$R$2*(COS($R$1)+COS(S15)) -> 0.012257461 | U15: =IF($Q$2, $R$2*(SIN($R$1)+SIN(S15)), -0.5) -> -0.5
... B50: 0.011872429 | C50: =IF($A$1=0, 0, IF(B50<=$A$2, ($A$1/$A$2^2)*(2*$A$2*B50-B50^2), ($A$1/(1-$A$2)^2)*((1-2*$A$2)+2*$A$2*B50-B50^2))) -> 0.0011696236 | D50: =IF($Q$3, 5*$A$3*(0.2969*SQRT(B50)-0.126*B50-0.3516*B50^2+0.2843*B50^3-0.1036*B50^4), 5*$A$3*(0.2969*SQRT(B50)-0.126*B50-0.3516*B50^2+0.2843*B50^3-0.1015*B50^4)) -> 0.018483248 | E50: =IF($A$1=0, 0, IF(B50<=$A$2, ($A$1/$A$2^2) *(2*$A$2-2*B50), ($A$1/(1-$A$2)^2)*(2*$A$2-2*B50))) -> 0.097031893 | F50: =IF($A$1=0, 0, ATAN(E50)) -> 0.096729077 | G50: =B50-D50*SIN(F50) -> 0.010087349 | H50: =C50+D50*COS(F50) -> 0.01956647 | I50: =B50+D50*SIN(F50) -> 0.01365751 | J50: =C50-D50*COS(F50) -> -0.017227222 | M50: =IF($Q$1, C50, -0.5) -> -0.5 | S50: 6.2831853 | T50: =$R$2*(COS($R$1)+COS(S50)) -> 0.031655115 | U50: =IF($Q$2, $R$2*(SIN($R$1)+SIN(S50)), -0.5) -> -0.5
B51: 0.012360952 | C51: =IF($A$1=0, 0, IF(B51<=$A$2, ($A$1/$A$2^2)*(2*$A$2*B51-B51^2), ($A$1/(1-$A$2)^2)*((1-2*$A$2)+2*$A$2*B51-B51^2))) -> 0.0012169961 | D51: =IF($Q$3, 5*$A$3*(0.2969*SQRT(B51)-0.126*B51-0.3516*B51^2+0.2843*B51^3-0.1036*B51^4), 5*$A$3*(0.2969*SQRT(B51)-0.126*B51-0.3516*B51^2+0.2843*B51^3-0.1015*B51^4)) -> 0.018839172 | E51: =IF($A$1=0, 0, IF(B51<=$A$2, ($A$1/$A$2^2) *(2*$A$2-2*B51), ($A$1/(1-$A$2)^2)*(2*$A$2-2*B51))) -> 0.096909762 | F51: =IF($A$1=0, 0, ATAN(E51)) -> 0.096608084 | G51: =B51-D51*SIN(F51) -> 0.010543766 | H51: =C51+D51*COS(F51) -> 0.019968323 | I51: =B51+D51*SIN(F51) -> 0.014178139 | J51: =C51-D51*COS(F51) -> -0.017534331 | M51: =IF($Q$1, C51, -0.5) -> -0.5
B52: 0.012859262 | C52: =IF($A$1=0, 0, IF(B52<=$A$2, ($A$1/$A$2^2)*(2*$A$2*B52-B52^2), ($A$1/(1-$A$2)^2)*((1-2*$A$2)+2*$A$2*B52-B52^2))) -> 0.0012652561 | D52: =IF($Q$3, 5*$A$3*(0.2969*SQRT(B52)-0.126*B52-0.3516*B52^2+0.2843*B52^3-0.1036*B52^4), 5*$A$3*(0.2969*SQRT(B52)-0.126*B52-0.3516*B52^2+0.2843*B52^3-0.1015*B52^4)) -> 0.019194158 | E52: =IF($A$1=0, 0, IF(B52<=$A$2, ($A$1/$A$2^2) *(2*$A$2-2*B52), ($A$1/(1-$A$2)^2)*(2*$A$2-2*B52))) -> 0.096785185 | F52: =IF($A$1=0, 0, ATAN(E52)) -> 0.096484664 | G52: =B52-D52*SIN(F52) -> 0.011010192 | H52: =C52+D52*COS(F52) -> 0.020370141 | I52: =B52+D52*SIN(F52) -> 0.014708331 | J52: =C52-D52*COS(F52) -> -0.017839629 | M52: =IF($Q$1, C52, -0.5) -> -0.5
B53: 0.013367353 | C53: =IF($A$1=0, 0, IF(B53<=$A$2, ($A$1/$A$2^2)*(2*$A$2*B53-B53^2), ($A$1/(1-$A$2)^2)*((1-2*$A$2)+2*$A$2*B53-B53^2))) -> 0.0013143995 | D53: =IF($Q$3, 5*$A$3*(0.2969*SQRT(B53)-0.126*B53-0.3516*B53^2+0.2843*B53^3-0.1036*B53^4), 5*$A$3*(0.2969*SQRT(B53)-0.126*B53-0.3516*B53^2+0.2843*B53^3-0.1015*B53^4)) -> 0.019548198 | E53: =IF($A$1=0, 0, IF(B53<=$A$2, ($A$1/$A$2^2) *(2*$A$2-2*B53), ($A$1/(1-$A$2)^2)*(2*$A$2-2*B53))) -> 0.096658162 | F53: =IF($A$1=0, 0, ATAN(E53)) -> 0.096358819 | G53: =B53-D53*SIN(F53) -> 0.011486625 | H53: =C53+D53*COS(F53) -> 0.020771915 | I53: =B53+D53*SIN(F53) -> 0.015248081 | J53: =C53-D53*COS(F53) -> -0.018143116 | M53: =IF($Q$1, C53, -0.5) -> -0.5
B54: 0.013885221 | C54: =IF($A$1=0, 0, IF(B54<=$A$2, ($A$1/$A$2^2)*(2*$A$2*B54-B54^2), ($A$1/(1-$A$2)^2)*((1-2*$A$2)+2*$A$2*B54-B54^2))) -> 0.0013644222 | D54: =IF($Q$3, 5*$A$3*(0.2969*SQRT(B54)-0.126*B54-0.3516*B54^2+0.2843*B54^3-0.1036*B54^4), 5*$A$3*(0.2969*SQRT(B54)-0.126*B54-0.3516*B54^2+0.2843*B54^3-0.1015*B54^4)) -> 0.019901287 | E54: =IF($A$1=0, 0, IF(B54<=$A$2, ($A$1/$A$2^2) *(2*$A$2-2*B54), ($A$1/(1-$A$2)^2)*(2*$A$2-2*B54))) -> 0.096528695 | F54: =IF($A$1=0, 0, ATAN(E54)) -> 0.096230549 | G54: =B54-D54*SIN(F54) -> 0.011973064 | H54: =C54+D54*COS(F54) -> 0.021173634 | I54: =B54+D54*SIN(F54) -> 0.015797378 | J54: =C54-D54*COS(F54) -> -0.018444789 | M54: =IF($Q$1, C54, -0.5) -> -0.5
B55: 0.01441286 | C55: =IF($A$1=0, 0, IF(B55<=$A$2, ($A$1/$A$2^2)*(2*$A$2*B55-B55^2), ($A$1/(1-$A$2)^2)*((1-2*$A$2)+2*$A$2*B55-B55^2))) -> 0.0014153197 | D55: =IF($Q$3, 5*$A$3*(0.2969*SQRT(B55)-0.126*B55-0.3516*B55^2+0.2843*B55^3-0.1036*B55^4), 5*$A$3*(0.2969*SQRT(B55)-0.126*B55-0.3516*B55^2+0.2843*B55^3-0.1015*B55^4)) -> 0.020253417 | E55: =IF($A$1=0, 0, IF(B55<=$A$2, ($A$1/$A$2^2) *(2*$A$2-2*B55), ($A$1/(1-$A$2)^2)*(2*$A$2-2*B55))) -> 0.096396785 | F55: =IF($A$1=0, 0, ATAN(E55)) -> 0.096099855 | G55: =B55-D55*SIN(F55) -> 0.012469504 | H55: =C55+D55*COS(F55) -> 0.021575286 | I55: =B55+D55*SIN(F55) -> 0.016356216 | J55: =C55-D55*COS(F55) -> -0.018744647 | M55: =IF($Q$1, C55, -0.5) -> -0.5
B56: 0.014950266 | C56: =IF($A$1=0, 0, IF(B56<=$A$2, ($A$1/$A$2^2)*(2*$A$2*B56-B56^2), ($A$1/(1-$A$2)^2)*((1-2*$A$2)+2*$A$2*B56-B56^2))) -> 0.0014670878 | D56: =IF($Q$3, 5*$A$3*(0.2969*SQRT(B56)-0.126*B56-0.3516*B56^2+0.2843*B56^3-0.1036*B56^4), 5*$A$3*(0.2969*SQRT(B56)-0.126*B56-0.3516*B56^2+0.2843*B56^3-0.1015*B56^4)) -> 0.020604581 | E56: =IF($A$1=0, 0, IF(B56<=$A$2, ($A$1/$A$2^2) *(2*$A$2-2*B56), ($A$1/(1-$A$2)^2)*(2*$A$2-2*B56))) -> 0.096262433 | F56: =IF($A$1=0, 0, ATAN(E56)) -> 0.095966738 | G56: =B56-D56*SIN(F56) -> 0.012975946 | H56: =C56+D56*COS(F56) -> 0.021976862 | I56: =B56+D56*SIN(F56) -> 0.016924587 | J56: =C56-D56*COS(F56) -> -0.019042686 | M56: =IF($Q$1, C56, -0.5) -> -0.5
B57: 0.015497433 | C57: =IF($A$1=0, 0, IF(B57<=$A$2, ($A$1/$A$2^2)*(2*$A$2*B57-B57^2), ($A$1/(1-$A$2)^2)*((1-2*$A$2)+2*$A$2*B57-B57^2))) -> 0.001519722 | D57: =IF($Q$3, 5*$A$3*(0.2969*SQRT(B57)-0.126*B57-0.3516*B57^2+0.2843*B57^3-0.1036*B57^4), 5*$A$3*(0.2969*SQRT(B57)-0.126*B57-0.3516*B57^2+0.2843*B57^3-0.1015*B57^4)) -> 0.020954774 | E57: =IF($A$1=0, 0, IF(B57<=$A$2, ($A$1/$A$2^2) *(2*$A$2-2*B57), ($A$1/(1-$A$2)^2)*(2*$A$2-2*B57))) -> 0.096125642 | F57: =IF($A$1=0, 0, ATAN(E57)) -> 0.095831201 | G57: =B57-D57*SIN(F57) -> 0.013492384 | H57: =C57+D57*COS(F57) -> 0.022378349 | I57: =B57+D57*SIN(F57) -> 0.017502482 | J57: =C57-D57*COS(F57) -> -0.019338905 | M57: =IF($Q$1, C57, -0.5) -> -0.5
B58: 0.016054356 | C58: =IF($A$1=0, 0, IF(B58<=$A$2, ($A$1/$A$2^2)*(2*$A$2*B58-B58^2), ($A$1/(1-$A$2)^2)*((1-2*$A$2)+2*$A$2*B58-B58^2))) -> 0.0015732178 | D58: =IF($Q$3, 5*$A$3*(0.2969*SQRT(B58)-0.126*B58-0.3516*B58^2+0.2843*B58^3-0.1036*B58^4), 5*$A$3*(0.2969*SQRT(B58)-0.126*B58-0.3516*B58^2+0.2843*B58^3-0.1015*B58^4)) -> 0.021303988 | E58: =IF($A$1=0, 0, IF(B58<=$A$2, ($A$1/$A$2^2) *(2*$A$2-2*B58), ($A$1/(1-$A$2)^2)*(2*$A$2-2*B58))) -> 0.095986411 | F58: =IF($A$1=0, 0, ATAN(E58)) -> 0.095693243 | G58: =B58-D58*SIN(F58) -> 0.014018818 | H58: =C58+D58*COS(F58) -> 0.022779738 | I58: =B58+D58*SIN(F58) -> 0.018089894 | J58: =C58-D58*COS(F58) -> -0.019633302 | M58: =IF($Q$1, C58, -0.5) -> -0.5
B59: 0.016621029 | C59: =IF($A$1=0, 0, IF(B59<=$A$2, ($A$1/$A$2^2)*(2*$A$2*B59-B59^2), ($A$1/(1-$A$2)^2)*((1-2*$A$2)+2*$A$2*B59-B59^2))) -> 0.0016275706 | D59: =IF($Q$3, 5*$A$3*(0.2969*SQRT(B59)-0.126*B59-0.3516*B59^2+0.2843*B59^3-0.1036*B59^4), 5*$A$3*(0.2969*SQRT(B59)-0.126*B59-0.3516*B59^2+0.2843*B59^3-0.1015*B59^4)) -> 0.021652216 | E59: =IF($A$1=0, 0, IF(B59<=$A$2, ($A$1/$A$2^2) *(2*$A$2-2*B59), ($A$1/(1-$A$2)^2)*(2*$A$2-2*B59))) -> 0.095844743 | F59: =IF($A$1=0, 0, ATAN(E59)) -> 0.095552866 | G59: =B59-D59*SIN(F59) -> 0.014555244 | H59: =C59+D59*COS(F59) -> 0.023181015 | I59: =B59+D59*SIN(F59) -> 0.018686813 | J59: =C59-D59*COS(F59) -> -0.019925874 | M59: =IF($Q$1, C59, -0.5) -> -0.5
B60: 0.017197446 | C60: =IF($A$1=0, 0, IF(B60<=$A$2, ($A$1/$A$2^2)*(2*$A$2*B60-B60^2), ($A$1/(1-$A$2)^2)*((1-2*$A$2)+2*$A$2*B60-B60^2))) -> 0.0016827756 | D60: =IF($Q$3, 5*$A$3*(0.2969*SQRT(B60)-0.126*B60-0.3516*B60^2+0.2843*B60^3-0.1036*B60^4), 5*$A$3*(0.2969*SQRT(B60)-0.126*B60-0.3516*B60^2+0.2843*B60^3-0.1015*B60^4)) -> 0.021999451 | E60: =IF($A$1=0, 0, IF(B60<=$A$2, ($A$1/$A$2^2) *(2*$A$2-2*B60), ($A$1/(1-$A$2)^2)*(2*$A$2-2*B60))) -> 0.095700639 | F60: =IF($A$1=0, 0, ATAN(E60)) -> 0.095410072 | G60: =B60-D60*SIN(F60) -> 0.01510166 | H60: =C60+D60*COS(F60) -> 0.023582171 | I60: =B60+D60*SIN(F60) -> 0.019293232 | J60: =C60-D60*COS(F60) -> -0.02021662 | M60: =IF($Q$1, C60, -0.5) -> -0.5
B61: 0.017783602 | C61: =IF($A$1=0, 0, IF(B61<=$A$2, ($A$1/$A$2^2)*(2*$A$2*B61-B61^2), ($A$1/(1-$A$2)^2)*((1-2*$A$2)+2*$A$2*B61-B61^2))) -> 0.0017388281 | D61: =IF($Q$3, 5*$A$3*(0.2969*SQRT(B61)-0.126*B61-0.3516*B61^2+0.2843*B61^3-0.1036*B61^4), 5*$A$3*(0.2969*SQRT(B61)-0.126*B61-0.3516*B61^2+0.2843*B61^3-0.1015*B61^4)) -> 0.022345686 | E61: =IF($A$1=0, 0, IF(B61<=$A$2, ($A$1/$A$2^2) *(2*$A$2-2*B61), ($A$1/(1-$A$2)^2)*(2*$A$2-2*B61))) -> 0.095554099 | F61: =IF($A$1=0, 0, ATAN(E61)) -> 0.095264861 | G61: =B61-D61*SIN(F61) -> 0.015658062 | H61: =C61+D61*COS(F61) -> 0.023983193 | I61: =B61+D61*SIN(F61) -> 0.019909142 | J61: =C61-D61*COS(F61) -> -0.020505536 | M61: =IF($Q$1, C61, -0.5) -> -0.5
B62: 0.018379491 | C62: =IF($A$1=0, 0, IF(B62<=$A$2, ($A$1/$A$2^2)*(2*$A$2*B62-B62^2), ($A$1/(1-$A$2)^2)*((1-2*$A$2)+2*$A$2*B62-B62^2))) -> 0.0017957234 | D62: =IF($Q$3, 5*$A$3*(0.2969*SQRT(B62)-0.126*B62-0.3516*B62^2+0.2843*B62^3-0.1036*B62^4), 5*$A$3*(0.2969*SQRT(B62)-0.126*B62-0.3516*B62^2+0.2843*B62^3-0.1015*B62^4)) -> 0.022690914 | E62: =IF($A$1=0, 0, IF(B62<=$A$2, ($A$1/$A$2^2) *(2*$A$2-2*B62), ($A$1/(1-$A$2)^2)*(2*$A$2-2*B62))) -> 0.095405127 | F62: =IF($A$1=0, 0, ATAN(E62)) -> 0.095117234 | G62: =B62-D62*SIN(F62) -> 0.016224447 | H62: =C62+D62*COS(F62) -> 0.024384069 | I62: =B62+D62*SIN(F62) -> 0.020534535 | J62: =C62-D62*COS(F62) -> -0.020792622 | M62: =IF($Q$1, C62, -0.5) -> -0.5
... B500: 1 | C500: =IF($A$1=0, 0, IF(B500<=$A$2, ($A$1/$A$2^2)*(2*$A$2*B500-B500^2), ($A$1/(1-$A$2)^2)*((1-2*$A$2)+2*$A$2*B500-B500^2))) -> 6.1679057e-18 | D500: =IF($Q$3, 5*$A$3*(0.2969*SQRT(B500)-0.126*B500-0.3516*B500^2+0.2843*B500^3-0.1036*B500^4), 5*$A$3*(0.2969*SQRT(B500)-0.126*B500-0.3516*B500^2+0.2843*B500^3-0.1015*B500^4)) -> 0.00126 | E500: =IF($A$1=0, 0, IF(B500<=$A$2, ($A$1/$A$2^2) *(2*$A$2-2*B500), ($A$1/(1-$A$2)^2)*(2*$A$2-2*B500))) -> -0.066666667 | F500: =IF($A$1=0, 0, ATAN(E500)) -> -0.066568164 | G500: =B500-D500*SIN(F500) -> 1.0000838 | H500: =C500+D500*COS(F500) -> 0.0012572093 | I500: =B500+D500*SIN(F500) -> 0.99991619 | J500: =C500-D500*COS(F500) -> -0.0012572093 | M500: =IF($Q$1, C500, -0.5) -> -0.5
G501: 1 | H501: 0 | I501: 1 | J501: 0

Sheet NACA_4-digit
A1: BACK | E1: Name | F1: =Data1!O1*1000+Data1!O2*100+Data1!O3 -> 2412
E2: Maximum Camber | F2: =IF(Data1!$P$1=1, "-", Data1!A1) -> 0.02 | H2: Leading-Edge Radius | I2: =Data1!R2 -> 0.01586693
E3: Position of Camber | F3: =IF(Data1!$P$1=1, "-", Data1!A2) -> 0.4 | H3: Trailing-Edge Angle | I3: =DEGREES(2*ATAN(1.16925*F4)) -> 15.97406
E4: Maximum Thickness | F4: =Data1!A3 -> 0.12

Sheet Data2
A1: 1000 | B1: {=1-COS((_xlfn.SEQUENCE(500,1,0,1)*PI())/(2*(500-1)))} -> 0 | C1: =IF(AND($Q$1=2, $A$3=1), 0, IF($T$3, 5*$A$7*(0.2969*SQRT(B1)-0.126*B1-0.3516*(B1^2)+0.2843*(B1^3)-0.1036*(B1^4)), 5*$A$7*(0.2969*SQRT(B1)-0.126*B1-0.3516*(B1^2)+0.2843*(B1^3)-0.1015*(B1^4)))) -> 0 | D1: =IF($Q$1=1, IF(B1<$A$8, ($A$10/6)*((B1^3)-3*$A$8*(B1^2)+($A$8^2)*(3-$A$8)*B1), (($A$10*($A$8^3))/6)*(1-B1)), " ") | E1: =IF($Q$1=1,IF(B1<$A$8, ($A$10/6)*(3*(B1^2)-6*$A$8*B1+($A$8^2)*(3-$A$8)), -($A$10*($A$8^3))/6), " ") | F1: =IF($Q$1=1, ATAN(E1), " ") | G1: =IF($Q$1=2, IF(A3<>1, IF(B1<$A$11, ($A$12/6)*((B1-$A$11)^3-$A$13*((1-$A$11)^3)*B1-($A$11^3)*B1+$A$11^3), ($A$12/6)*($A$13*(B1-$A$11)^3-$A$13*((1-$A$11)^3)*B1-($A$11^3)*B1+$A$11^3)), 0), " ") -> 0 | H1: =IF($Q$1=2, IF(A3<>1, IF(B1<$A$11, ($A$12/6)*(3*(B1-$A$11)^2-$A$13*((1-$A$11)^3)-($A$11^3)), ($A$12/6)*(3*$A$13*(B1-$A$11)^2-$A$13*((1-$A$11)^3)-($A$11^3))),0 ), " ") -> 0.33638763 | I1: =IF($Q$1=2, IF(A3<>1, ATAN(H1), 0), " ") -> 0.3244969 | J1: =IF($Q$1=1, D1, G1) -> 0 | K1: =IF($Q$1=1, F1, I1) -> 0.3244969 | L1: =B1-C1*SIN(K1) -> 0 | M1: =J1+C1*COS(K1) -> 0 | N1: =B1+C1*SIN(K1) -> 0 | O1: =J1-C1*COS(K1) -> 0 | P1: 0.2 | Q1: 2 | R1: =IF($T$1, J1, -0.5) -> -0.5 | T1: FALSE | U1: =ATAN(K1) -> 0.31377679 | V1: {=_xlfn.SEQUENCE(50, 1, 0, (2*PI())/(50-1))} -> 0 | W1: =$U$2*(COS($U$1)+COS(V1)) -> 0.030959151 | X1: =IF($T$2, $U$2*(SIN($U$1)+SIN(V1)), -0.5) -> -0.5
A2: 2 | B2: 4.9545967e-06 | C2: =IF(AND($Q$1=2, $A$3=1), 0, IF($T$3, 5*$A$7*(0.2969*SQRT(B2)-0.126*B2-0.3516*(B2^2)+0.2843*(B2^3)-0.1036*(B2^4)), 5*$A$7*(0.2969*SQRT(B2)-0.126*B2-0.3516*(B2^2)+0.2843*(B2^3)-0.1015*(B2^4)))) -> 0.00039614589 | D2: =IF($Q$1=1, IF(B2<$A$8, ($A$10/6)*((B2^3)-3*$A$8*(B2^2)+($A$8^2)*(3-$A$8)*B2), (($A$10*($A$8^3))/6)*(1-B2)), " ") | E2: =IF($Q$1=1,IF(B2<$A$8, ($A$10/6)*(3*(B2^2)-6*$A$8*B2+($A$8^2)*(3-$A$8)), -($A$10*($A$8^3))/6), " ") | F2: =IF($Q$1=1, ATAN(E2), " ") | G2: =IF($Q$1=2, IF(A4<>1, IF(B2<$A$11, ($A$12/6)*((B2-$A$11)^3-$A$13*((1-$A$11)^3)*B2-($A$11^3)*B2+$A$11^3), ($A$12/6)*($A$13*(B2-$A$11)^3-$A$13*((1-$A$11)^3)*B2-($A$11^3)*B2+$A$11^3)), 0), " ") -> 1.666623e-06 | H2: =IF($Q$1=2, IF(A4<>1, IF(B2<$A$11, ($A$12/6)*(3*(B2-$A$11)^2-$A$13*((1-$A$11)^3)-($A$11^3)), ($A$12/6)*(3*$A$13*(B2-$A$11)^2-$A$13*((1-$A$11)^3)-($A$11^3))),0 ), " ") -> 0.33637065 | I2: =IF($Q$1=2, IF(A4<>1, ATAN(H2), 0), " ") -> 0.32448164 | J2: =IF($Q$1=1, D2, G2) -> 1.666623e-06 | K2: =IF($Q$1=1, F2, I2) -> 0.32448164 | L2: =B2-C2*SIN(K2) -> -0.00012134365 | M2: =J2+C2*COS(K2) -> 0.00037714008 | N2: =B2+C2*SIN(K2) -> 0.00013125285 | O2: =J2-C2*COS(K2) -> -0.00037380683 | P2: =P1-(P1-P1*SQRT(P1/3)-$A$5)/(1-SQRT(3*P1)/2) -> 0.20267631 | R2: =IF($T$1, J2, -0.5) -> -0.5 | T2: FALSE | U2: =(0.2969^2/2)*(A7/0.2)^2 -> 0.01586693 | V2: 0.12822827 | W2: =$U$2*(COS($U$1)+COS(V2)) -> 0.030828884 | X2: =IF($T$2, $U$2*(SIN($U$1)+SIN(V2)), -0.5) -> -0.5
A3: 3 | B3: 1.9818338e-05 | C3: =IF(AND($Q$1=2, $A$3=1), 0, IF($T$3, 5*$A$7*(0.2969*SQRT(B3)-0.126*B3-0.3516*(B3^2)+0.2843*(B3^3)-0.1036*(B3^4)), 5*$A$7*(0.2969*SQRT(B3)-0.126*B3-0.3516*(B3^2)+0.2843*(B3^3)-0.1015*(B3^4)))) -> 0.00079154159 | D3: =IF($Q$1=1, IF(B3<$A$8, ($A$10/6)*((B3^3)-3*$A$8*(B3^2)+($A$8^2)*(3-$A$8)*B3), (($A$10*($A$8^3))/6)*(1-B3)), " ") | E3: =IF($Q$1=1,IF(B3<$A$8, ($A$10/6)*(3*(B3^2)-6*$A$8*B3+($A$8^2)*(3-$A$8)), -($A$10*($A$8^3))/6), " ") | F3: =IF($Q$1=1, ATAN(E3), " ") | G3: =IF($Q$1=2, IF(A5<>1, IF(B3<$A$11, ($A$12/6)*((B3-$A$11)^3-$A$13*((1-$A$11)^3)*B3-($A$11^3)*B3+$A$11^3), ($A$12/6)*($A$13*(B3-$A$11)^3-$A$13*((1-$A$11)^3)*B3-($A$11^3)*B3+$A$11^3)), 0), " ") -> 6.6659706e-06 | H3: =IF($Q$1=2, IF(A5<>1, IF(B3<$A$11, ($A$12/6)*(3*(B3-$A$11)^2-$A$13*((1-$A$11)^3)-($A$11^3)), ($A$12/6)*(3*$A$13*(B3-$A$11)^2-$A$13*((1-$A$11)^3)-($A$11^3))),0 ), " ") -> 0.33631971 | I3: =IF($Q$1=2, IF(A5<>1, ATAN(H3), 0), " ") -> 0.32443588 | J3: =IF($Q$1=1, D3, G3) -> 6.6659706e-06 | K3: =IF($Q$1=1, F3, I3) -> 0.32443588 | L3: =B3-C3*SIN(K3) -> -0.00023250466 | M3: =J3+C3*COS(K3) -> 0.00075691339 | N3: =B3+C3*SIN(K3) -> 0.00027214134 | O3: =J3-C3*COS(K3) -> -0.00074358145 | P3: =P2-(P2-P2*SQRT(P2/3)-$A$5)/(1-SQRT(3*P2)/2) -> 0.20268198 | R3: =IF($T$1, J3, -0.5) -> -0.5 | T3: FALSE | V3: 0.25645654 | W3: =$U$2*(COS($U$1)+COS(V3)) -> 0.030440221 | X3: =IF($T$2, $U$2*(SIN($U$1)+SIN(V3)), -0.5) -> -0.5
A4: 12 | B4: 4.4591076e-05 | C4: =IF(AND($Q$1=2, $A$3=1), 0, IF($T$3, 5*$A$7*(0.2969*SQRT(B4)-0.126*B4-0.3516*(B4^2)+0.2843*(B4^3)-0.1036*(B4^4)), 5*$A$7*(0.2969*SQRT(B4)-0.126*B4-0.3516*(B4^2)+0.2843*(B4^3)-0.1015*(B4^4)))) -> 0.0011861859 | D4: =IF($Q$1=1, IF(B4<$A$8, ($A$10/6)*((B4^3)-3*$A$8*(B4^2)+($A$8^2)*(3-$A$8)*B4), (($A$10*($A$8^3))/6)*(1-B4)), " ") | E4: =IF($Q$1=1,IF(B4<$A$8, ($A$10/6)*(3*(B4^2)-6*$A$8*B4+($A$8^2)*(3-$A$8)), -($A$10*($A$8^3))/6), " ") | F4: =IF($Q$1=1, ATAN(E4), " ") | G4: =IF($Q$1=2, IF(A6<>1, IF(B4<$A$11, ($A$12/6)*((B4-$A$11)^3-$A$13*((1-$A$11)^3)*B4-($A$11^3)*B4+$A$11^3), ($A$12/6)*($A$13*(B4-$A$11)^3-$A$13*((1-$A$11)^3)*B4-($A$11^3)*B4+$A$11^3)), 0), " ") -> 1.4996479e-05 | H4: =IF($Q$1=2, IF(A6<>1, IF(B4<$A$11, ($A$12/6)*(3*(B4-$A$11)^2-$A$13*((1-$A$11)^3)-($A$11^3)), ($A$12/6)*(3*$A$13*(B4-$A$11)^2-$A$13*((1-$A$11)^3)-($A$11^3))),0 ), " ") -> 0.33623483 | I4: =IF($Q$1=2, IF(A6<>1, ATAN(H4), 0), " ") -> 0.32435962 | J4: =IF($Q$1=1, D4, G4) -> 1.4996479e-05 | K4: =IF($Q$1=1, F4, I4) -> 0.32435962 | L4: =B4-C4*SIN(K4) -> -0.0003334486 | M4: =J4+C4*COS(K4) -> 0.0011393288 | N4: =B4+C4*SIN(K4) -> 0.00042263075 | O4: =J4-C4*COS(K4) -> -0.0011093358 | P4: =P3-(P3-P3*SQRT(P3/3)-$A$5)/(1-SQRT(3*P3)/2) -> 0.20268198 | R4: =IF($T$1, J4, -0.5) -> -0.5 | V4: 0.38468481 | W4: =$U$2*(COS($U$1)+COS(V4)) -> 0.029799544 | X4: =IF($T$2, $U$2*(SIN($U$1)+SIN(V4)), -0.5) -> -0.5
A5: =0.05*$A$3 -> 0.15 | B5: 7.9272565e-05 | C5: =IF(AND($Q$1=2, $A$3=1), 0, IF($T$3, 5*$A$7*(0.2969*SQRT(B5)-0.126*B5-0.3516*(B5^2)+0.2843*(B5^3)-0.1036*(B5^4)), 5*$A$7*(0.2969*SQRT(B5)-0.126*B5-0.3516*(B5^2)+0.2843*(B5^3)-0.1015*(B5^4)))) -> 0.0015800777 | D5: =IF($Q$1=1, IF(B5<$A$8, ($A$10/6)*((B5^3)-3*$A$8*(B5^2)+($A$8^2)*(3-$A$8)*B5), (($A$10*($A$8^3))/6)*(1-B5)), " ") | E5: =IF($Q$1=1,IF(B5<$A$8, ($A$10/6)*(3*(B5^2)-6*$A$8*B5+($A$8^2)*(3-$A$8)), -($A$10*($A$8^3))/6), " ") | F5: =IF($Q$1=1, ATAN(E5), " ") | G5: =IF($Q$1=2, IF(A7<>1, IF(B5<$A$11, ($A$12/6)*((B5-$A$11)^3-$A$13*((1-$A$11)^3)*B5-($A$11^3)*B5+$A$11^3), ($A$12/6)*($A$13*(B5-$A$11)^3-$A$13*((1-$A$11)^3)*B5-($A$11^3)*B5+$A$11^3)), 0), " ") -> 2.6655543e-05 | H5: =IF($Q$1=2, IF(A7<>1, IF(B5<$A$11, ($A$12/6)*(3*(B5-$A$11)^2-$A$13*((1-$A$11)^3)-($A$11^3)), ($A$12/6)*(3*$A$13*(B5-$A$11)^2-$A$13*((1-$A$11)^3)-($A$11^3))),0 ), " ") -> 0.33611601 | I5: =IF($Q$1=2, IF(A7<>1, ATAN(H5), 0), " ") -> 0.32425287 | J5: =IF($Q$1=1, D5, G5) -> 2.6655543e-05 | K5: =IF($Q$1=1, F5, I5) -> 0.32425287 | L5: =B5-C5*SIN(K5) -> -0.00042414125 | M5: =J5+C5*COS(K5) -> 0.0015243938 | N5: =B5+C5*SIN(K5) -> 0.00058268638 | O5: =J5-C5*COS(K5) -> -0.0014710828 | P5: =P4-(P4-P4*SQRT(P4/3)-$A$5)/(1-SQRT(3*P4)/2) -> 0.20268198 | R5: =IF($T$1, J5, -0.5) -> -0.5 | V5: 0.51291309 | W5: =$U$2*(COS($U$1)+COS(V5)) -> 0.028917374 | X5: =IF($T$2, $U$2*(SIN($U$1)+SIN(V5)), -0.5) -> -0.5
A6: =IF(Q1=1, A2/100, 0.02) -> 0.02 | B6: 0.00012386246 | C6: =IF(AND($Q$1=2, $A$3=1), 0, IF($T$3, 5*$A$7*(0.2969*SQRT(B6)-0.126*B6-0.3516*(B6^2)+0.2843*(B6^3)-0.1036*(B6^4)), 5*$A$7*(0.2969*SQRT(B6)-0.126*B6-0.3516*(B6^2)+0.2843*(B6^3)-0.1015*(B6^4)))) -> 0.0019732154 | D6: =IF($Q$1=1, IF(B6<$A$8, ($A$10/6)*((B6^3)-3*$A$8*(B6^2)+($A$8^2)*(3-$A$8)*B6), (($A$10*($A$8^3))/6)*(1-B6)), " ") | E6: =IF($Q$1=1,IF(B6<$A$8, ($A$10/6)*(3*(B6^2)-6*$A$8*B6+($A$8^2)*(3-$A$8)), -($A$10*($A$8^3))/6), " ") | F6: =IF($Q$1=1, ATAN(E6), " ") | G6: =IF($Q$1=2, IF(A8<>1, IF(B6<$A$11, ($A$12/6)*((B6-$A$11)^3-$A$13*((1-$A$11)^3)*B6-($A$11^3)*B6+$A$11^3), ($A$12/6)*($A$13*(B6-$A$11)^3-$A$13*((1-$A$11)^3)*B6-($A$11^3)*B6+$A$11^3)), 0), " ") -> 4.1639516e-05 | H6: =IF($Q$1=2, IF(A8<>1, IF(B6<$A$11, ($A$12/6)*(3*(B6-$A$11)^2-$A$13*((1-$A$11)^3)-($A$11^3)), ($A$12/6)*(3*$A$13*(B6-$A$11)^2-$A$13*((1-$A$11)^3)-($A$11^3))),0 ), " ") -> 0.33596326 | I6: =IF($Q$1=2, IF(A8<>1, ATAN(H6), 0), " ") -> 0.32411562 | J6: =IF($Q$1=1, D6, G6) -> 4.1639516e-05 | K6: =IF($Q$1=1, F6, I6) -> 0.32411562 | L6: =B6-C6*SIN(K6) -> -0.00050454859 | M6: =J6+C6*COS(K6) -> 0.001912115 | N6: =B6+C6*SIN(K6) -> 0.00075227352 | O6: =J6-C6*COS(K6) -> -0.001828836 | P6: =P5-(P5-P5*SQRT(P5/3)-$A$5)/(1-SQRT(3*P5)/2) -> 0.20268198 | R6: =IF($T$1, J6, -0.5) -> -0.5 | V6: 0.64114136 | W6: =$U$2*(COS($U$1)+COS(V6)) -> 0.027808195 | X6: =IF($T$2, $U$2*(SIN($U$1)+SIN(V6)), -0.5) -> -0.5
A7: =A4/100 -> 0.12 | B7: 0.00017836033 | C7: =IF(AND($Q$1=2, $A$3=1), 0, IF($T$3, 5*$A$7*(0.2969*SQRT(B7)-0.126*B7-0.3516*(B7^2)+0.2843*(B7^3)-0.1036*(B7^4)), 5*$A$7*(0.2969*SQRT(B7)-0.126*B7-0.3516*(B7^2)+0.2843*(B7^3)-0.1015*(B7^4)))) -> 0.0023655976 | D7: =IF($Q$1=1, IF(B7<$A$8, ($A$10/6)*((B7^3)-3*$A$8*(B7^2)+($A$8^2)*(3-$A$8)*B7), (($A$10*($A$8^3))/6)*(1-B7)), " ") | E7: =IF($Q$1=1,IF(B7<$A$8, ($A$10/6)*(3*(B7^2)-6*$A$8*B7+($A$8^2)*(3-$A$8)), -($A$10*($A$8^3))/6), " ") | F7: =IF($Q$1=1, ATAN(E7), " ") | G7: =IF($Q$1=2, IF(A9<>1, IF(B7<$A$11, ($A$12/6)*((B7-$A$11)^3-$A$13*((1-$A$11)^3)*B7-($A$11^3)*B7+$A$11^3), ($A$12/6)*($A$13*(B7-$A$11)^3-$A$13*((1-$A$11)^3)*B7-($A$11^3)*B7+$A$11^3)), 0), " ") -> 5.994371e-05 | H7: =IF($Q$1=2, IF(A9<>1, IF(B7<$A$11, ($A$12/6)*(3*(B7-$A$11)^2-$A$13*((1-$A$11)^3)-($A$11^3)), ($A$12/6)*(3*$A$13*(B7-$A$11)^2-$A$13*((1-$A$11)^3)-($A$11^3))),0 ), " ") -> 0.33577663 | I7: =IF($Q$1=2, IF(A9<>1, ATAN(H7), 0), " ") -> 0.3239479 | J7: =IF($Q$1=1, D7, G7) -> 5.994371e-05 | K7: =IF($Q$1=1, F7, I7) -> 0.3239479 | L7: =B7-C7*SIN(K7) -> -0.00057463682 | M7: =J7+C7*COS(K7) -> 0.0023024975 | N7: =B7+C7*SIN(K7) -> 0.00093135747 | O7: =J7-C7*COS(K7) -> -0.0021826101 | P7: =P6-(P6-P6*SQRT(P6/3)-$A$5)/(1-SQRT(3*P6)/2) -> 0.20268198 | R7: =IF($T$1, J7, -0.5) -> -0.5 | V7: 0.76936963 | W7: =$U$2*(COS($U$1)+COS(V7)) -> 0.02649022 | X7: =IF($T$2, $U$2*(SIN($U$1)+SIN(V7)), -0.5) -> -0.5
A8: =IF(Q1=1, IF(A3=1, 0.058, IF(A3=2, 0.126, IF(A3=3, 0.2025, IF(A3=4, 0.29, 0.391)))), 0) -> 0 | B8: 0.00024276562 | C8: =IF(AND($Q$1=2, $A$3=1), 0, IF($T$3, 5*$A$7*(0.2969*SQRT(B8)-0.126*B8-0.3516*(B8^2)+0.2843*(B8^3)-0.1036*(B8^4)), 5*$A$7*(0.2969*SQRT(B8)-0.126*B8-0.3516*(B8^2)+0.2843*(B8^3)-0.1015*(B8^4)))) -> 0.0027572227 | D8: =IF($Q$1=1, IF(B8<$A$8, ($A$10/6)*((B8^3)-3*$A$8*(B8^2)+($A$8^2)*(3-$A$8)*B8), (($A$10*($A$8^3))/6)*(1-B8)), " ") | E8: =IF($Q$1=1,IF(B8<$A$8, ($A$10/6)*(3*(B8^2)-6*$A$8*B8+($A$8^2)*(3-$A$8)), -($A$10*($A$8^3))/6), " ") | F8: =IF($Q$1=1, ATAN(E8), " ") | G8: =IF($Q$1=2, IF(A10<>1, IF(B8<$A$11, ($A$12/6)*((B8-$A$11)^3-$A$13*((1-$A$11)^3)*B8-($A$11^3)*B8+$A$11^3), ($A$12/6)*($A$13*(B8-$A$11)^3-$A$13*((1-$A$11)^3)*B8-($A$11^3)*B8+$A$11^3)), 0), " ") -> 8.15624e-05 | H8: =IF($Q$1=2, IF(A10<>1, IF(B8<$A$11, ($A$12/6)*(3*(B8-$A$11)^2-$A$13*((1-$A$11)^3)-($A$11^3)), ($A$12/6)*(3*$A$13*(B8-$A$11)^2-$A$13*((1-$A$11)^3)-($A$11^3))),0 ), " ") -> 0.33555612 | I8: =IF($Q$1=2, IF(A10<>1, ATAN(H8), 0), " ") -> 0.32374972 | J8: =IF($Q$1=1, D8, G8) -> 8.15624e-05 | K8: =IF($Q$1=1, F8, I8) -> 0.32374972 | L8: =B8-C8*SIN(K8) -> -0.00063437231 | M8: =J8+C8*COS(K8) -> 0.0026955452 | N8: =B8+C8*SIN(K8) -> 0.0011199035 | O8: =J8-C8*COS(K8) -> -0.0025324204 | P8: =P7-(P7-P7*SQRT(P7/3)-$A$5)/(1-SQRT(3*P7)/2) -> 0.20268198 | R8: =IF($T$1, J8, -0.5) -> -0.5 | V8: 0.8975979 | W8: =$U$2*(COS($U$1)+COS(V8)) -> 0.02498509 | X8: =IF($T$2, $U$2*(SIN($U$1)+SIN(V8)), -0.5) -> -0.5
A9: =IF(Q1=1, (3*A8-7*A8^2+8*A8^3-4*A8^4)/SQRT(A8-A8^2)-1.5*(1-2*A8)*(PI()/2-ASIN(1-2*A8)), 0) -> 0 | B9: 0.00031707769 | C9: =IF(AND($Q$1=2, $A$3=1), 0, IF($T$3, 5*$A$7*(0.2969*SQRT(B9)-0.126*B9-0.3516*(B9^2)+0.2843*(B9^3)-0.1036*(B9^4)), 5*$A$7*(0.2969*SQRT(B9)-0.126*B9-0.3516*(B9^2)+0.2843*(B9^3)-0.1015*(B9^4)))) -> 0.0031480889 | D9: =IF($Q$1=1, IF(B9<$A$8, ($A$10/6)*((B9^3)-3*$A$8*(B9^2)+($A$8^2)*(3-$A$8)*B9), (($A$10*($A$8^3))/6)*(1-B9)), " ") | E9: =IF($Q$1=1,IF(B9<$A$8, ($A$10/6)*(3*(B9^2)-6*$A$8*B9+($A$8^2)*(3-$A$8)), -($A$10*($A$8^3))/6), " ") | F9: =IF($Q$1=1, ATAN(E9), " ") | G9: =IF($Q$1=2, IF(A11<>1, IF(B9<$A$11, ($A$12/6)*((B9-$A$11)^3-$A$13*((1-$A$11)^3)*B9-($A$11^3)*B9+$A$11^3), ($A$12/6)*($A$13*(B9-$A$11)^3-$A$13*((1-$A$11)^3)*B9-($A$11^3)*B9+$A$11^3)), 0), " ") -> 0.00010648882 | H9: =IF($Q$1=2, IF(A11<>1, IF(B9<$A$11, ($A$12/6)*(3*(B9-$A$11)^2-$A$13*((1-$A$11)^3)-($A$11^3)), ($A$12/6)*(3*$A$13*(B9-$A$11)^2-$A$13*((1-$A$11)^3)-($A$11^3))),0 ), " ") -> 0.33530177 | I9: =IF($Q$1=2, IF(A11<>1, ATAN(H9), 0), " ") -> 0.3235211 | J9: =IF($Q$1=1, D9, G9) -> 0.00010648882 | K9: =IF($Q$1=1, F9, I9) -> 0.3235211 | L9: =B9-C9*SIN(K9) -> -0.00068372167 | M9: =J9+C9*COS(K9) -> 0.0030912609 | N9: =B9+C9*SIN(K9) -> 0.0013178771 | O9: =J9-C9*COS(K9) -> -0.0028782833 | P9: =P8-(P8-P8*SQRT(P8/3)-$A$5)/(1-SQRT(3*P8)/2) -> 0.20268198 | R9: =IF($T$1, J9, -0.5) -> -0.5 | V9: 1.0258262 | W9: =$U$2*(COS($U$1)+COS(V9)) -> 0.02331752 | X9: =IF($T$2, $U$2*(SIN($U$1)+SIN(V9)), -0.5) -> -0.5
A10: =IF(Q1=1, (6*0.15*A2)/A9, 0) -> 0 | B10: 0.00040129582 | C10: =IF(AND($Q$1=2, $A$3=1), 0, IF($T$3, 5*$A$7*(0.2969*SQRT(B10)-0.126*B10-0.3516*(B10^2)+0.2843*(B10^3)-0.1036*(B10^4)), 5*$A$7*(0.2969*SQRT(B10)-0.126*B10-0.3516*(B10^2)+0.2843*(B10^3)-0.1015*(B10^4)))) -> 0.0035381943 | D10: =IF($Q$1=1, IF(B10<$A$8, ($A$10/6)*((B10^3)-3*$A$8*(B10^2)+($A$8^2)*(3-$A$8)*B10), (($A$10*($A$8^3))/6)*(1-B10)), " ") | E10: =IF($Q$1=1,IF(B10<$A$8, ($A$10/6)*(3*(B10^2)-6*$A$8*B10+($A$8^2)*(3-$A$8)), -($A$10*($A$8^3))/6), " ") | F10: =IF($Q$1=1, ATAN(E10), " ") | G10: =IF($Q$1=2, IF(A12<>1, IF(B10<$A$11, ($A$12/6)*((B10-$A$11)^3-$A$13*((1-$A$11)^3)*B10-($A$11^3)*B10+$A$11^3), ($A$12/6)*($A$13*(B10-$A$11)^3-$A$13*((1-$A$11)^3)*B10-($A$11^3)*B10+$A$11^3)), 0), " ") -> 0.00013471517 | H10: =IF($Q$1=2, IF(A12<>1, IF(B10<$A$11, ($A$12/6)*(3*(B10-$A$11)^2-$A$13*((1-$A$11)^3)-($A$11^3)), ($A$12/6)*(3*$A$13*(B10-$A$11)^2-$A$13*((1-$A$11)^3)-($A$11^3))),0 ), " ") -> 0.33501363 | I10: =IF($Q$1=2, IF(A12<>1, ATAN(H10), 0), " ") -> 0.32326206 | J10: =IF($Q$1=1, D10, G10) -> 0.00013471517 | K10: =IF($Q$1=1, F10, I10) -> 0.32326206 | L10: =B10-C10*SIN(K10) -> -0.00072265174 | M10: =J10+C10*COS(K10) -> 0.003489646 | N10: =B10+C10*SIN(K10) -> 0.0015252434 | O10: =J10-C10*COS(K10) -> -0.0032202157 | P10: =P9-(P9-P9*SQRT(P9/3)-$A$5)/(1-SQRT(3*P9)/2) -> 0.20268198 | R10: =IF($T$1, J10, -0.5) -> -0.5 | V10: 1.1540544 | W10: =$U$2*(COS($U$1)+COS(V10)) -> 0.02151489 | X10: =IF($T$2, $U$2*(SIN($U$1)+SIN(V10)), -0.5) -> -0.5
A11: =IF(Q1=2, IF(A3=2, 0.13, IF(A3=3, 0.217, IF(A3=4, 0.318, IF(A3=5, 0.441, 0)))), 0) -> 0.217 | B11: 0.00049541917 | C11: =IF(AND($Q$1=2, $A$3=1), 0, IF($T$3, 5*$A$7*(0.2969*SQRT(B11)-0.126*B11-0.3516*(B11^2)+0.2843*(B11^3)-0.1036*(B11^4)), 5*$A$7*(0.2969*SQRT(B11)-0.126*B11-0.3516*(B11^2)+0.2843*(B11^3)-0.1015*(B11^4)))) -> 0.0039275371 | D11: =IF($Q$1=1, IF(B11<$A$8, ($A$10/6)*((B11^3)-3*$A$8*(B11^2)+($A$8^2)*(3-$A$8)*B11), (($A$10*($A$8^3))/6)*(1-B11)), " ") | E11: =IF($Q$1=1,IF(B11<$A$8, ($A$10/6)*(3*(B11^2)-6*$A$8*B11+($A$8^2)*(3-$A$8)), -($A$10*($A$8^3))/6), " ") | F11: =IF($Q$1=1, ATAN(E11), " ") | G11: =IF($Q$1=2, IF(A13<>1, IF(B11<$A$11, ($A$12/6)*((B11-$A$11)^3-$A$13*((1-$A$11)^3)*B11-($A$11^3)*B11+$A$11^3), ($A$12/6)*($A$13*(B11-$A$11)^3-$A$13*((1-$A$11)^3)*B11-($A$11^3)*B11+$A$11^3)), 0), " ") -> 0.00016623263 | H11: =IF($Q$1=2, IF(A13<>1, IF(B11<$A$11, ($A$12/6)*(3*(B11-$A$11)^2-$A$13*((1-$A$11)^3)-($A$11^3)), ($A$12/6)*(3*$A$13*(B11-$A$11)^2-$A$13*((1-$A$11)^3)-($A$11^3))),0 ), " ") -> 0.33469173 | I11: =IF($Q$1=2, IF(A13<>1, ATAN(H11), 0), " ") -> 0.32297261 | J11: =IF($Q$1=1, D11, G11) -> 0.00016623263 | K11: =IF($Q$1=1, F11, I11) -> 0.32297261 | L11: =B11-C11*SIN(K11) -> -0.00075112954 | M11: =J11+C11*COS(K11) -> 0.0038907009 | N11: =B11+C11*SIN(K11) -> 0.0017419679 | O11: =J11-C11*COS(K11) -> -0.0035582356 | P11: =P10-(P10-P10*SQRT(P10/3)-$A$5)/(1-SQRT(3*P10)/2) -> 0.20268198 | R11: =IF($T$1, J11, -0.5) -> -0.5 | V11: 1.2822827 | W11: =$U$2*(COS($U$1)+COS(V11)) -> 0.0196068 | X11: =IF($T$2, $U$2*(SIN($U$1)+SIN(V11)), -0.5) -> -0.5
A12: =IF(Q1=2, IF(A3=2, 51.99, IF(A3=3, 15.793, IF(A3=4, 6.52, IF(A3=5, 3.191,0)))), 0) -> 15.793 | B12: 0.0005994468 | C12: =IF(AND($Q$1=2, $A$3=1), 0, IF($T$3, 5*$A$7*(0.2969*SQRT(B12)-0.126*B12-0.3516*(B12^2)+0.2843*(B12^3)-0.1036*(B12^4)), 5*$A$7*(0.2969*SQRT(B12)-0.126*B12-0.3516*(B12^2)+0.2843*(B12^3)-0.1015*(B12^4)))) -> 0.004316115 | D12: =IF($Q$1=1, IF(B12<$A$8, ($A$10/6)*((B12^3)-3*$A$8*(B12^2)+($A$8^2)*(3-$A$8)*B12), (($A$10*($A$8^3))/6)*(1-B12)), " ") | E12: =IF($Q$1=1,IF(B12<$A$8, ($A$10/6)*(3*(B12^2)-6*$A$8*B12+($A$8^2)*(3-$A$8)), -($A$10*($A$8^3))/6), " ") | F12: =IF($Q$1=1, ATAN(E12), " ") | G12: =IF($Q$1=2, IF(A14<>1, IF(B12<$A$11, ($A$12/6)*((B12-$A$11)^3-$A$13*((1-$A$11)^3)*B12-($A$11^3)*B12+$A$11^3), ($A$12/6)*($A$13*(B12-$A$11)^3-$A$13*((1-$A$11)^3)*B12-($A$11^3)*B12+$A$11^3)), 0), " ") -> 0.00020103132 | H12: =IF($Q$1=2, IF(A14<>1, IF(B12<$A$11, ($A$12/6)*(3*(B12-$A$11)^2-$A$13*((1-$A$11)^3)-($A$11^3)), ($A$12/6)*(3*$A$13*(B12-$A$11)^2-$A$13*((1-$A$11)^3)-($A$11^3))),0 ), " ") -> 0.33433611 | I12: =IF($Q$1=2, IF(A14<>1, ATAN(H12), 0), " ") -> 0.32265279 | J12: =IF($Q$1=1, D12, G12) -> 0.00020103132 | K12: =IF($Q$1=1, F12, I12) -> 0.32265279 | L12: =B12-C12*SIN(K12) -> -0.00076912236 | M12: =J12+C12*COS(K12) -> 0.0042944244 | N12: =B12+C12*SIN(K12) -> 0.0019680159 | O12: =J12-C12*COS(K12) -> -0.0038923618 | P12: =P11-(P11-P11*SQRT(P11/3)-$A$5)/(1-SQRT(3*P11)/2) -> 0.20268198 | R12: =IF($T$1, J12, -0.5) -> -0.5 | V12: 1.410511 | W12: =$U$2*(COS($U$1)+COS(V12)) -> 0.017624582 | X12: =IF($T$2, $U$2*(SIN($U$1)+SIN(V12)), -0.5) -> -0.5
A13: =IF(Q1=2, IF(A3<>1, IF(A3=2, 0.000764,IF(A3=3, 0.00677,IF(A3=4, 0.0303, 0.1355))), 0), 0) -> 0.00677 | B13: 0.00071337768 | C13: =IF(AND($Q$1=2, $A$3=1), 0, IF($T$3, 5*$A$7*(0.2969*SQRT(B13)-0.126*B13-0.3516*(B13^2)+0.2843*(B13^3)-0.1036*(B13^4)), 5*$A$7*(0.2969*SQRT(B13)-0.126*B13-0.3516*(B13^2)+0.2843*(B13^3)-0.1015*(B13^4)))) -> 0.0047039259 | D13: =IF($Q$1=1, IF(B13<$A$8, ($A$10/6)*((B13^3)-3*$A$8*(B13^2)+($A$8^2)*(3-$A$8)*B13), (($A$10*($A$8^3))/6)*(1-B13)), " ") | E13: =IF($Q$1=1,IF(B13<$A$8, ($A$10/6)*(3*(B13^2)-6*$A$8*B13+($A$8^2)*(3-$A$8)), -($A$10*($A$8^3))/6), " ") | F13: =IF($Q$1=1, ATAN(E13), " ") | G13: =IF($Q$1=2, IF(A15<>1, IF(B13<$A$11, ($A$12/6)*((B13-$A$11)^3-$A$13*((1-$A$11)^3)*B13-($A$11^3)*B13+$A$11^3), ($A$12/6)*($A$13*(B13-$A$11)^3-$A$13*((1-$A$11)^3)*B13-($A$11^3)*B13+$A$11^3)), 0), " ") -> 0.00023910035 | H13: =IF($Q$1=2, IF(A15<>1, IF(B13<$A$11, ($A$12/6)*(3*(B13-$A$11)^2-$A$13*((1-$A$11)^3)-($A$11^3)), ($A$12/6)*(3*$A$13*(B13-$A$11)^2-$A$13*((1-$A$11)^3)-($A$11^3))),0 ), " ") -> 0.33394684 | I13: =IF($Q$1=2, IF(A15<>1, ATAN(H13), 0), " ") -> 0.32230261 | J13: =IF($Q$1=1, D13, G13) -> 0.00023910035 | K13: =IF($Q$1=1, F13, I13) -> 0.32230261 | L13: =B13-C13*SIN(K13) -> -0.00077659767 | M13: =J13+C13*COS(K13) -> 0.0047008145 | N13: =B13+C13*SIN(K13) -> 0.002203353 | O13: =J13-C13*COS(K13) -> -0.0042226138 | P13: =P12-(P12-P12*SQRT(P12/3)-$A$5)/(1-SQRT(3*P12)/2) -> 0.20268198 | R13: =IF($T$1, J13, -0.5) -> -0.5 | V13: 1.5387393 | W13: =$U$2*(COS($U$1)+COS(V13)) -> 0.015600781 | X13: =IF($T$2, $U$2*(SIN($U$1)+SIN(V13)), -0.5) -> -0.5
A14: =IF(Q1=2, 0.3, 0.15*A2) -> 0.3 | B14: 0.00083721069 | C14: =IF(AND($Q$1=2, $A$3=1), 0, IF($T$3, 5*$A$7*(0.2969*SQRT(B14)-0.126*B14-0.3516*(B14^2)+0.2843*(B14^3)-0.1036*(B14^4)), 5*$A$7*(0.2969*SQRT(B14)-0.126*B14-0.3516*(B14^2)+0.2843*(B14^3)-0.1015*(B14^4)))) -> 0.0050909675 | D14: =IF($Q$1=1, IF(B14<$A$8, ($A$10/6)*((B14^3)-3*$A$8*(B14^2)+($A$8^2)*(3-$A$8)*B14), (($A$10*($A$8^3))/6)*(1-B14)), " ") | E14: =IF($Q$1=1,IF(B14<$A$8, ($A$10/6)*(3*(B14^2)-6*$A$8*B14+($A$8^2)*(3-$A$8)), -($A$10*($A$8^3))/6), " ") | F14: =IF($Q$1=1, ATAN(E14), " ") | G14: =IF($Q$1=2, IF(A16<>1, IF(B14<$A$11, ($A$12/6)*((B14-$A$11)^3-$A$13*((1-$A$11)^3)*B14-($A$11^3)*B14+$A$11^3), ($A$12/6)*($A$13*(B14-$A$11)^3-$A$13*((1-$A$11)^3)*B14-($A$11^3)*B14+$A$11^3)), 0), " ") -> 0.0002804278 | H14: =IF($Q$1=2, IF(A16<>1, IF(B14<$A$11, ($A$12/6)*(3*(B14-$A$11)^2-$A$13*((1-$A$11)^3)-($A$11^3)), ($A$12/6)*(3*$A$13*(B14-$A$11)^2-$A$13*((1-$A$11)^3)-($A$11^3))),0 ), " ") -> 0.33352398 | I14: =IF($Q$1=2, IF(A16<>1, ATAN(H14), 0), " ") -> 0.32192212 | J14: =IF($Q$1=1, D14, G14) -> 0.0002804278 | K14: =IF($Q$1=1, F14, I14) -> 0.32192212 | L14: =B14-C14*SIN(K14) -> -0.00077352321 | M14: =J14+C14*COS(K14) -> 0.0051098674 | N14: =B14+C14*SIN(K14) -> 0.0024479446 | O14: =J14-C14*COS(K14) -> -0.0045490118 | P14: =P13-(P13-P13*SQRT(P13/3)-$A$5)/(1-SQRT(3*P13)/2) -> 0.20268198 | R14: =IF($T$1, J14, -0.5) -> -0.5 | V14: 1.6669675 | W14: =$U$2*(COS($U$1)+COS(V14)) -> 0.013568631 | X14: =IF($T$2, $U$2*(SIN($U$1)+SIN(V14)), -0.5) -> -0.5
B15: 0.00097094459 | C15: =IF(AND($Q$1=2, $A$3=1), 0, IF($T$3, 5*$A$7*(0.2969*SQRT(B15)-0.126*B15-0.3516*(B15^2)+0.2843*(B15^3)-0.1036*(B15^4)), 5*$A$7*(0.2969*SQRT(B15)-0.126*B15-0.3516*(B15^2)+0.2843*(B15^3)-0.1015*(B15^4)))) -> 0.0054772374 | D15: =IF($Q$1=1, IF(B15<$A$8, ($A$10/6)*((B15^3)-3*$A$8*(B15^2)+($A$8^2)*(3-$A$8)*B15), (($A$10*($A$8^3))/6)*(1-B15)), " ") | E15: =IF($Q$1=1,IF(B15<$A$8, ($A$10/6)*(3*(B15^2)-6*$A$8*B15+($A$8^2)*(3-$A$8)), -($A$10*($A$8^3))/6), " ") | F15: =IF($Q$1=1, ATAN(E15), " ") | G15: =IF($Q$1=2, IF(A17<>1, IF(B15<$A$11, ($A$12/6)*((B15-$A$11)^3-$A$13*((1-$A$11)^3)*B15-($A$11^3)*B15+$A$11^3), ($A$12/6)*($A$13*(B15-$A$11)^3-$A$13*((1-$A$11)^3)*B15-($A$11^3)*B15+$A$11^3)), 0), " ") -> 0.00032500075 | H15: =IF($Q$1=2, IF(A17<>1, IF(B15<$A$11, ($A$12/6)*(3*(B15-$A$11)^2-$A$13*((1-$A$11)^3)-($A$11^3)), ($A$12/6)*(3*$A$13*(B15-$A$11)^2-$A$13*((1-$A$11)^3)-($A$11^3))),0 ), " ") -> 0.33306757 | I15: =IF($Q$1=2, IF(A17<>1, ATAN(H15), 0), " ") -> 0.32151135 | J15: =IF($Q$1=1, D15, G15) -> 0.00032500075 | K15: =IF($Q$1=1, F15, I15) -> 0.32151135 | L15: =B15-C15*SIN(K15) -> -0.00075986694 | M15: =J15+C15*COS(K15) -> 0.0055215785 | N15: =B15+C15*SIN(K15) -> 0.0027017561 | O15: =J15-C15*COS(K15) -> -0.004871577 | P15: =P14-(P14-P14*SQRT(P14/3)-$A$5)/(1-SQRT(3*P14)/2) -> 0.20268198 | R15: =IF($T$1, J15, -0.5) -> -0.5 | V15: 1.7951958 | W15: =$U$2*(COS($U$1)+COS(V15)) -> 0.011561497 | X15: =IF($T$2, $U$2*(SIN($U$1)+SIN(V15)), -0.5) -> -0.5
B16: 0.0011145781 | C16: =IF(AND($Q$1=2, $A$3=1), 0, IF($T$3, 5*$A$7*(0.2969*SQRT(B16)-0.126*B16-0.3516*(B16^2)+0.2843*(B16^3)-0.1036*(B16^4)), 5*$A$7*(0.2969*SQRT(B16)-0.126*B16-0.3516*(B16^2)+0.2843*(B16^3)-0.1015*(B16^4)))) -> 0.0058627329 | D16: =IF($Q$1=1, IF(B16<$A$8, ($A$10/6)*((B16^3)-3*$A$8*(B16^2)+($A$8^2)*(3-$A$8)*B16), (($A$10*($A$8^3))/6)*(1-B16)), " ") | E16: =IF($Q$1=1,IF(B16<$A$8, ($A$10/6)*(3*(B16^2)-6*$A$8*B16+($A$8^2)*(3-$A$8)), -($A$10*($A$8^3))/6), " ") | F16: =IF($Q$1=1, ATAN(E16), " ") | G16: =IF($Q$1=2, IF(A18<>1, IF(B16<$A$11, ($A$12/6)*((B16-$A$11)^3-$A$13*((1-$A$11)^3)*B16-($A$11^3)*B16+$A$11^3), ($A$12/6)*($A$13*(B16-$A$11)^3-$A$13*((1-$A$11)^3)*B16-($A$11^3)*B16+$A$11^3)), 0), " ") -> 0.00037280521 | H16: =IF($Q$1=2, IF(A18<>1, IF(B16<$A$11, ($A$12/6)*(3*(B16-$A$11)^2-$A$13*((1-$A$11)^3)-($A$11^3)), ($A$12/6)*(3*$A$13*(B16-$A$11)^2-$A$13*((1-$A$11)^3)-($A$11^3))),0 ), " ") -> 0.33257769 | I16: =IF($Q$1=2, IF(A18<>1, ATAN(H16), 0), " ") -> 0.32107032 | J16: =IF($Q$1=1, D16, G16) -> 0.00037280521 | K16: =IF($Q$1=1, F16, I16) -> 0.32107032 | L16: =B16-C16*SIN(K16) -> -0.00073559706 | M16: =J16+C16*COS(K16) -> 0.0059359418 | N16: =B16+C16*SIN(K16) -> 0.0029647532 | O16: =J16-C16*COS(K16) -> -0.0051903314 | P16: =P15-(P15-P15*SQRT(P15/3)-$A$5)/(1-SQRT(3*P15)/2) -> 0.20268198 | R16: =IF($T$1, J16, -0.5) -> -0.5 | V16: 1.9234241 | W16: =$U$2*(COS($U$1)+COS(V16)) -> 0.0096123381 | X16: =IF($T$2, $U$2*(SIN($U$1)+SIN(V16)), -0.5) -> -0.5
B17: 0.0012681097 | C17: =IF(AND($Q$1=2, $A$3=1), 0, IF($T$3, 5*$A$7*(0.2969*SQRT(B17)-0.126*B17-0.3516*(B17^2)+0.2843*(B17^3)-0.1036*(B17^4)), 5*$A$7*(0.2969*SQRT(B17)-0.126*B17-0.3516*(B17^2)+0.2843*(B17^3)-0.1015*(B17^4)))) -> 0.0062474514 | D17: =IF($Q$1=1, IF(B17<$A$8, ($A$10/6)*((B17^3)-3*$A$8*(B17^2)+($A$8^2)*(3-$A$8)*B17), (($A$10*($A$8^3))/6)*(1-B17)), " ") | E17: =IF($Q$1=1,IF(B17<$A$8, ($A$10/6)*(3*(B17^2)-6*$A$8*B17+($A$8^2)*(3-$A$8)), -($A$10*($A$8^3))/6), " ") | F17: =IF($Q$1=1, ATAN(E17), " ") | G17: =IF($Q$1=2, IF(A19<>1, IF(B17<$A$11, ($A$12/6)*((B17-$A$11)^3-$A$13*((1-$A$11)^3)*B17-($A$11^3)*B17+$A$11^3), ($A$12/6)*($A$13*(B17-$A$11)^3-$A$13*((1-$A$11)^3)*B17-($A$11^3)*B17+$A$11^3)), 0), " ") -> 0.00042382623 | H17: =IF($Q$1=2, IF(A19<>1, IF(B17<$A$11, ($A$12/6)*(3*(B17-$A$11)^2-$A$13*((1-$A$11)^3)-($A$11^3)), ($A$12/6)*(3*$A$13*(B17-$A$11)^2-$A$13*((1-$A$11)^3)-($A$11^3))),0 ), " ") -> 0.33205441 | I17: =IF($Q$1=2, IF(A19<>1, ATAN(H17), 0), " ") -> 0.32059908 | J17: =IF($Q$1=1, D17, G17) -> 0.00042382623 | K17: =IF($Q$1=1, F17, I17) -> 0.32059908 | L17: =B17-C17*SIN(K17) -> -0.00070068202 | M17: =J17+C17*COS(K17) -> 0.00635295 | N17: =B17+C17*SIN(K17) -> 0.0032369014 | O17: =J17-C17*COS(K17) -> -0.0055052975 | P17: =P16-(P16-P16*SQRT(P16/3)-$A$5)/(1-SQRT(3*P16)/2) -> 0.20268198 | R17: =IF($T$1, J17, -0.5) -> -0.5 | V17: 2.0516523 | W17: =$U$2*(COS($U$1)+COS(V17)) -> 0.0077531586 | X17: =IF($T$2, $U$2*(SIN($U$1)+SIN(V17)), -0.5) -> -0.5
B18: 0.0014315379 | C18: =IF(AND($Q$1=2, $A$3=1), 0, IF($T$3, 5*$A$7*(0.2969*SQRT(B18)-0.126*B18-0.3516*(B18^2)+0.2843*(B18^3)-0.1036*(B18^4)), 5*$A$7*(0.2969*SQRT(B18)-0.126*B18-0.3516*(B18^2)+0.2843*(B18^3)-0.1015*(B18^4)))) -> 0.0066313902 | D18: =IF($Q$1=1, IF(B18<$A$8, ($A$10/6)*((B18^3)-3*$A$8*(B18^2)+($A$8^2)*(3-$A$8)*B18), (($A$10*($A$8^3))/6)*(1-B18)), " ") | E18: =IF($Q$1=1,IF(B18<$A$8, ($A$10/6)*(3*(B18^2)-6*$A$8*B18+($A$8^2)*(3-$A$8)), -($A$10*($A$8^3))/6), " ") | F18: =IF($Q$1=1, ATAN(E18), " ") | G18: =IF($Q$1=2, IF(A20<>1, IF(B18<$A$11, ($A$12/6)*((B18-$A$11)^3-$A$13*((1-$A$11)^3)*B18-($A$11^3)*B18+$A$11^3), ($A$12/6)*($A$13*(B18-$A$11)^3-$A$13*((1-$A$11)^3)*B18-($A$11^3)*B18+$A$11^3)), 0), " ") -> 0.00047804782 | H18: =IF($Q$1=2, IF(A20<>1, IF(B18<$A$11, ($A$12/6)*(3*(B18-$A$11)^2-$A$13*((1-$A$11)^3)-($A$11^3)), ($A$12/6)*(3*$A$13*(B18-$A$11)^2-$A$13*((1-$A$11)^3)-($A$11^3))),0 ), " ") -> 0.33149782 | I18: =IF($Q$1=2, IF(A20<>1, ATAN(H18), 0), " ") -> 0.32009768 | J18: =IF($Q$1=1, D18, G18) -> 0.00047804782 | K18: =IF($Q$1=1, F18, I18) -> 0.32009768 | L18: =B18-C18*SIN(K18) -> -0.00065509052 | M18: =J18+C18*COS(K18) -> 0.0067725945 | N18: =B18+C18*SIN(K18) -> 0.0035181664 | O18: =J18-C18*COS(K18) -> -0.0058164989 | P18: =P17-(P17-P17*SQRT(P17/3)-$A$5)/(1-SQRT(3*P17)/2) -> 0.20268198 | R18: =IF($T$1, J18, -0.5) -> -0.5 | V18: 2.1798806 | W18: =$U$2*(COS($U$1)+COS(V18)) -> 0.0060144863 | X18: =IF($T$2, $U$2*(SIN($U$1)+SIN(V18)), -0.5) -> -0.5
B19: 0.0016048612 | C19: =IF(AND($Q$1=2, $A$3=1), 0, IF($T$3, 5*$A$7*(0.2969*SQRT(B19)-0.126*B19-0.3516*(B19^2)+0.2843*(B19^3)-0.1036*(B19^4)), 5*$A$7*(0.2969*SQRT(B19)-0.126*B19-0.3516*(B19^2)+0.2843*(B19^3)-0.1015*(B19^4)))) -> 0.0070145463 | D19: =IF($Q$1=1, IF(B19<$A$8, ($A$10/6)*((B19^3)-3*$A$8*(B19^2)+($A$8^2)*(3-$A$8)*B19), (($A$10*($A$8^3))/6)*(1-B19)), " ") | E19: =IF($Q$1=1,IF(B19<$A$8, ($A$10/6)*(3*(B19^2)-6*$A$8*B19+($A$8^2)*(3-$A$8)), -($A$10*($A$8^3))/6), " ") | F19: =IF($Q$1=1, ATAN(E19), " ") | G19: =IF($Q$1=2, IF(A21<>1, IF(B19<$A$11, ($A$12/6)*((B19-$A$11)^3-$A$13*((1-$A$11)^3)*B19-($A$11^3)*B19+$A$11^3), ($A$12/6)*($A$13*(B19-$A$11)^3-$A$13*((1-$A$11)^3)*B19-($A$11^3)*B19+$A$11^3)), 0), " ") -> 0.00053545298 | H19: =IF($Q$1=2, IF(A21<>1, IF(B19<$A$11, ($A$12/6)*(3*(B19-$A$11)^2-$A$13*((1-$A$11)^3)-($A$11^3)), ($A$12/6)*(3*$A$13*(B19-$A$11)^2-$A$13*((1-$A$11)^3)-($A$11^3))),0 ), " ") -> 0.33090798 | I19: =IF($Q$1=2, IF(A21<>1, ATAN(H19), 0), " ") -> 0.31956615 | J19: =IF($Q$1=1, D19, G19) -> 0.00053545298 | K19: =IF($Q$1=1, F19, I19) -> 0.31956615 | L19: =B19-C19*SIN(K19) -> -0.00059879152 | M19: =J19+C19*COS(K19) -> 0.0071948655 | N19: =B19+C19*SIN(K19) -> 0.0038085139 | O19: =J19-C19*COS(K19) -> -0.0061239595 | P19: =P18-(P18-P18*SQRT(P18/3)-$A$5)/(1-SQRT(3*P18)/2) -> 0.20268198 | R19: =IF($T$1, J19, -0.5) -> -0.5 | V19: 2.3081089 | W19: =$U$2*(COS($U$1)+COS(V19)) -> 0.0044248702 | X19: =IF($T$2, $U$2*(SIN($U$1)+SIN(V19)), -0.5) -> -0.5
B20: 0.0017880778 | C20: =IF(AND($Q$1=2, $A$3=1), 0, IF($T$3, 5*$A$7*(0.2969*SQRT(B20)-0.126*B20-0.3516*(B20^2)+0.2843*(B20^3)-0.1036*(B20^4)), 5*$A$7*(0.2969*SQRT(B20)-0.126*B20-0.3516*(B20^2)+0.2843*(B20^3)-0.1015*(B20^4)))) -> 0.0073969168 | D20: =IF($Q$1=1, IF(B20<$A$8, ($A$10/6)*((B20^3)-3*$A$8*(B20^2)+($A$8^2)*(3-$A$8)*B20), (($A$10*($A$8^3))/6)*(1-B20)), " ") | E20: =IF($Q$1=1,IF(B20<$A$8, ($A$10/6)*(3*(B20^2)-6*$A$8*B20+($A$8^2)*(3-$A$8)), -($A$10*($A$8^3))/6), " ") | F20: =IF($Q$1=1, ATAN(E20), " ") | G20: =IF($Q$1=2, IF(A22<>1, IF(B20<$A$11, ($A$12/6)*((B20-$A$11)^3-$A$13*((1-$A$11)^3)*B20-($A$11^3)*B20+$A$11^3), ($A$12/6)*($A$13*(B20-$A$11)^3-$A$13*((1-$A$11)^3)*B20-($A$11^3)*B20+$A$11^3)), 0), " ") -> 0.00059602372 | H20: =IF($Q$1=2, IF(A22<>1, IF(B20<$A$11, ($A$12/6)*(3*(B20-$A$11)^2-$A$13*((1-$A$11)^3)-($A$11^3)), ($A$12/6)*(3*$A$13*(B20-$A$11)^2-$A$13*((1-$A$11)^3)-($A$11^3))),0 ), " ") -> 0.33028499 | I20: =IF($Q$1=2, IF(A22<>1, ATAN(H20), 0), " ") -> 0.31900454 | J20: =IF($Q$1=1, D20, G20) -> 0.00059602372 | K20: =IF($Q$1=1, F20, I20) -> 0.31900454 | L20: =B20-C20*SIN(K20) -> -0.00053175423 | M20: =J20+C20*COS(K20) -> 0.0076197519 | N20: =B20+C20*SIN(K20) -> 0.0041079097 | O20: =J20-C20*COS(K20) -> -0.0064277045 | P20: =P19-(P19-P19*SQRT(P19/3)-$A$5)/(1-SQRT(3*P19)/2) -> 0.20268198 | R20: =IF($T$1, J20, -0.5) -> -0.5 | V20: 2.4363372 | W20: =$U$2*(COS($U$1)+COS(V20)) -> 0.0030104116 | X20: =IF($T$2, $U$2*(SIN($U$1)+SIN(V20)), -0.5) -> -0.5
B21: 0.0019811858 | C21: =IF(AND($Q$1=2, $A$3=1), 0, IF($T$3, 5*$A$7*(0.2969*SQRT(B21)-0.126*B21-0.3516*(B21^2)+0.2843*(B21^3)-0.1036*(B21^4)), 5*$A$7*(0.2969*SQRT(B21)-0.126*B21-0.3516*(B21^2)+0.2843*(B21^3)-0.1015*(B21^4)))) -> 0.0077784985 | D21: =IF($Q$1=1, IF(B21<$A$8, ($A$10/6)*((B21^3)-3*$A$8*(B21^2)+($A$8^2)*(3-$A$8)*B21), (($A$10*($A$8^3))/6)*(1-B21)), " ") | E21: =IF($Q$1=1,IF(B21<$A$8, ($A$10/6)*(3*(B21^2)-6*$A$8*B21+($A$8^2)*(3-$A$8)), -($A$10*($A$8^3))/6), " ") | F21: =IF($Q$1=1, ATAN(E21), " ") | G21: =IF($Q$1=2, IF(A23<>1, IF(B21<$A$11, ($A$12/6)*((B21-$A$11)^3-$A$13*((1-$A$11)^3)*B21-($A$11^3)*B21+$A$11^3), ($A$12/6)*($A$13*(B21-$A$11)^3-$A$13*((1-$A$11)^3)*B21-($A$11^3)*B21+$A$11^3)), 0), " ") -> 0.00065974105 | H21: =IF($Q$1=2, IF(A23<>1, IF(B21<$A$11, ($A$12/6)*(3*(B21-$A$11)^2-$A$13*((1-$A$11)^3)-($A$11^3)), ($A$12/6)*(3*$A$13*(B21-$A$11)^2-$A$13*((1-$A$11)^3)-($A$11^3))),0 ), " ") -> 0.32962894 | I21: =IF($Q$1=2, IF(A23<>1, ATAN(H21), 0), " ") -> 0.3184129 | J21: =IF($Q$1=1, D21, G21) -> 0.00065974105 | K21: =IF($Q$1=1, F21, I21) -> 0.3184129 | L21: =B21-C21*SIN(K21) -> -0.00045394812 | M21: =J21+C21*COS(K21) -> 0.0080472414 | N21: =B21+C21*SIN(K21) -> 0.0044163197 | O21: =J21-C21*COS(K21) -> -0.0067277593 | R21: =IF($T$1, J21, -0.5) -> -0.5 | V21: 2.5645654 | W21: =$U$2*(COS($U$1)+COS(V21)) -> 0.0017943361 | X21: =IF($T$2, $U$2*(SIN($U$1)+SIN(V21)), -0.5) -> -0.5
B22: 0.0021841834 | C22: =IF(AND($Q$1=2, $A$3=1), 0, IF($T$3, 5*$A$7*(0.2969*SQRT(B22)-0.126*B22-0.3516*(B22^2)+0.2843*(B22^3)-0.1036*(B22^4)), 5*$A$7*(0.2969*SQRT(B22)-0.126*B22-0.3516*(B22^2)+0.2843*(B22^3)-0.1015*(B22^4)))) -> 0.0081592881 | D22: =IF($Q$1=1, IF(B22<$A$8, ($A$10/6)*((B22^3)-3*$A$8*(B22^2)+($A$8^2)*(3-$A$8)*B22), (($A$10*($A$8^3))/6)*(1-B22)), " ") | E22: =IF($Q$1=1,IF(B22<$A$8, ($A$10/6)*(3*(B22^2)-6*$A$8*B22+($A$8^2)*(3-$A$8)), -($A$10*($A$8^3))/6), " ") | F22: =IF($Q$1=1, ATAN(E22), " ") | G22: =IF($Q$1=2, IF(A24<>1, IF(B22<$A$11, ($A$12/6)*((B22-$A$11)^3-$A$13*((1-$A$11)^3)*B22-($A$11^3)*B22+$A$11^3), ($A$12/6)*($A$13*(B22-$A$11)^3-$A$13*((1-$A$11)^3)*B22-($A$11^3)*B22+$A$11^3)), 0), " ") -> 0.00072658498 | H22: =IF($Q$1=2, IF(A24<>1, IF(B22<$A$11, ($A$12/6)*(3*(B22-$A$11)^2-$A$13*((1-$A$11)^3)-($A$11^3)), ($A$12/6)*(3*$A$13*(B22-$A$11)^2-$A$13*((1-$A$11)^3)-($A$11^3))),0 ), " ") -> 0.32893993 | I22: =IF($Q$1=2, IF(A24<>1, ATAN(H22), 0), " ") -> 0.31779129 | J22: =IF($Q$1=1, D22, G22) -> 0.00072658498 | K22: =IF($Q$1=1, F22, I22) -> 0.31779129 | L22: =B22-C22*SIN(K22) -> -0.00036534294 | M22: =J22+C22*COS(K22) -> 0.0084773203 | N22: =B22+C22*SIN(K22) -> 0.0047337097 | O22: =J22-C22*COS(K22) -> -0.0070241503 | R22: =IF($T$1, J22, -0.5) -> -0.5 | V22: 2.6927937 | W22: =$U$2*(COS($U$1)+COS(V22)) -> 0.00079661142 | X22: =IF($T$2, $U$2*(SIN($U$1)+SIN(V22)), -0.5) -> -0.5
B23: 0.0023970685 | C23: =IF(AND($Q$1=2, $A$3=1), 0, IF($T$3, 5*$A$7*(0.2969*SQRT(B23)-0.126*B23-0.3516*(B23^2)+0.2843*(B23^3)-0.1036*(B23^4)), 5*$A$7*(0.2969*SQRT(B23)-0.126*B23-0.3516*(B23^2)+0.2843*(B23^3)-0.1015*(B23^4)))) -> 0.0085392824 | D23: =IF($Q$1=1, IF(B23<$A$8, ($A$10/6)*((B23^3)-3*$A$8*(B23^2)+($A$8^2)*(3-$A$8)*B23), (($A$10*($A$8^3))/6)*(1-B23)), " ") | E23: =IF($Q$1=1,IF(B23<$A$8, ($A$10/6)*(3*(B23^2)-6*$A$8*B23+($A$8^2)*(3-$A$8)), -($A$10*($A$8^3))/6), " ") | F23: =IF($Q$1=1, ATAN(E23), " ") | G23: =IF($Q$1=2, IF(A25<>1, IF(B23<$A$11, ($A$12/6)*((B23-$A$11)^3-$A$13*((1-$A$11)^3)*B23-($A$11^3)*B23+$A$11^3), ($A$12/6)*($A$13*(B23-$A$11)^3-$A$13*((1-$A$11)^3)*B23-($A$11^3)*B23+$A$11^3)), 0), " ") -> 0.00079653455 | H23: =IF($Q$1=2, IF(A25<>1, IF(B23<$A$11, ($A$12/6)*(3*(B23-$A$11)^2-$A$13*((1-$A$11)^3)-($A$11^3)), ($A$12/6)*(3*$A$13*(B23-$A$11)^2-$A$13*((1-$A$11)^3)-($A$11^3))),0 ), " ") -> 0.32821805 | I23: =IF($Q$1=2, IF(A25<>1, ATAN(H23), 0), " ") -> 0.31713976 | J23: =IF($Q$1=1, D23, G23) -> 0.00079653455 | K23: =IF($Q$1=1, F23, I23) -> 0.31713976 | L23: =B23-C23*SIN(K23) -> -0.00026590872 | M23: =J23+C23*COS(K23) -> 0.0089099738 | N23: =B23+C23*SIN(K23) -> 0.0050600457 | O23: =J23-C23*COS(K23) -> -0.0073169047 | R23: =IF($T$1, J23, -0.5) -> -0.5 | V23: 2.821022 | W23: =$U$2*(COS($U$1)+COS(V23)) -> 3.3620283e-05 | X23: =IF($T$2, $U$2*(SIN($U$1)+SIN(V23)), -0.5) -> -0.5
B24: 0.0026198391 | C24: =IF(AND($Q$1=2, $A$3=1), 0, IF($T$3, 5*$A$7*(0.2969*SQRT(B24)-0.126*B24-0.3516*(B24^2)+0.2843*(B24^3)-0.1036*(B24^4)), 5*$A$7*(0.2969*SQRT(B24)-0.126*B24-0.3516*(B24^2)+0.2843*(B24^3)-0.1015*(B24^4)))) -> 0.0089184778 | D24: =IF($Q$1=1, IF(B24<$A$8, ($A$10/6)*((B24^3)-3*$A$8*(B24^2)+($A$8^2)*(3-$A$8)*B24), (($A$10*($A$8^3))/6)*(1-B24)), " ") | E24: =IF($Q$1=1,IF(B24<$A$8, ($A$10/6)*(3*(B24^2)-6*$A$8*B24+($A$8^2)*(3-$A$8)), -($A$10*($A$8^3))/6), " ") | F24: =IF($Q$1=1, ATAN(E24), " ") | G24: =IF($Q$1=2, IF(A26<>1, IF(B24<$A$11, ($A$12/6)*((B24-$A$11)^3-$A$13*((1-$A$11)^3)*B24-($A$11^3)*B24+$A$11^3), ($A$12/6)*($A$13*(B24-$A$11)^3-$A$13*((1-$A$11)^3)*B24-($A$11^3)*B24+$A$11^3)), 0), " ") -> 0.00086956781 | H24: =IF($Q$1=2, IF(A26<>1, IF(B24<$A$11, ($A$12/6)*(3*(B24-$A$11)^2-$A$13*((1-$A$11)^3)-($A$11^3)), ($A$12/6)*(3*$A$13*(B24-$A$11)^2-$A$13*((1-$A$11)^3)-($A$11^3))),0 ), " ") -> 0.32746343 | I24: =IF($Q$1=2, IF(A26<>1, ATAN(H24), 0), " ") -> 0.31645837 | J24: =IF($Q$1=1, D24, G24) -> 0.00086956781 | K24: =IF($Q$1=1, F24, I24) -> 0.31645837 | L24: =B24-C24*SIN(K24) -> -0.00015561576 | M24: =J24+C24*COS(K24) -> 0.0093451856 | N24: =B24+C24*SIN(K24) -> 0.0053952939 | O24: =J24-C24*COS(K24) -> -0.00760605 | R24: =IF($T$1, J24, -0.5) -> -0.5 | V24: 2.9492502 | W24: =$U$2*(COS($U$1)+COS(V24)) -> -0.00048210904 | X24: =IF($T$2, $U$2*(SIN($U$1)+SIN(V24)), -0.5) -> -0.5
B25: 0.0028524929 | C25: =IF(AND($Q$1=2, $A$3=1), 0, IF($T$3, 5*$A$7*(0.2969*SQRT(B25)-0.126*B25-0.3516*(B25^2)+0.2843*(B25^3)-0.1036*(B25^4)), 5*$A$7*(0.2969*SQRT(B25)-0.126*B25-0.3516*(B25^2)+0.2843*(B25^3)-0.1015*(B25^4)))) -> 0.0092968709 | D25: =IF($Q$1=1, IF(B25<$A$8, ($A$10/6)*((B25^3)-3*$A$8*(B25^2)+($A$8^2)*(3-$A$8)*B25), (($A$10*($A$8^3))/6)*(1-B25)), " ") | E25: =IF($Q$1=1,IF(B25<$A$8, ($A$10/6)*(3*(B25^2)-6*$A$8*B25+($A$8^2)*(3-$A$8)), -($A$10*($A$8^3))/6), " ") | F25: =IF($Q$1=1, ATAN(E25), " ") | G25: =IF($Q$1=2, IF(A27<>1, IF(B25<$A$11, ($A$12/6)*((B25-$A$11)^3-$A$13*((1-$A$11)^3)*B25-($A$11^3)*B25+$A$11^3), ($A$12/6)*($A$13*(B25-$A$11)^3-$A$13*((1-$A$11)^3)*B25-($A$11^3)*B25+$A$11^3)), 0), " ") -> 0.00094566182 | H25: =IF($Q$1=2, IF(A27<>1, IF(B25<$A$11, ($A$12/6)*(3*(B25-$A$11)^2-$A$13*((1-$A$11)^3)-($A$11^3)), ($A$12/6)*(3*$A$13*(B25-$A$11)^2-$A$13*((1-$A$11)^3)-($A$11^3))),0 ), " ") -> 0.32667616 | I25: =IF($Q$1=2, IF(A27<>1, ATAN(H25), 0), " ") -> 0.31574718 | J25: =IF($Q$1=1, D25, G25) -> 0.00094566182 | K25: =IF($Q$1=1, F25, I25) -> 0.31574718 | L25: =B25-C25*SIN(K25) -> -3.4434656e-05 | M25: =J25+C25*COS(K25) -> 0.0097829384 | N25: =B25+C25*SIN(K25) -> 0.0057394205 | O25: =J25-C25*COS(K25) -> -0.0078916148 | R25: =IF($T$1, J25, -0.5) -> -0.5 | V25: 3.0774785 | W25: =$U$2*(COS($U$1)+COS(V25)) -> -0.00074210829 | X25: =IF($T$2, $U$2*(SIN($U$1)+SIN(V25)), -0.5) -> -0.5
